[2024-12-20T17:37:24.074+0000] {local_task_job_runner.py:123} INFO - ::group::Pre task execution logs
[2024-12-20T17:37:24.093+0000] {taskinstance.py:2613} INFO - Dependencies all met for dep_context=non-requeueable deps ti=<TaskInstance: docker_dag.t2 manual__2024-12-20T17:37:06.900846+00:00 [queued]>
[2024-12-20T17:37:24.122+0000] {taskinstance.py:2613} INFO - Dependencies all met for dep_context=requeueable deps ti=<TaskInstance: docker_dag.t2 manual__2024-12-20T17:37:06.900846+00:00 [queued]>
[2024-12-20T17:37:24.122+0000] {taskinstance.py:2866} INFO - Starting attempt 1 of 1
[2024-12-20T17:37:24.143+0000] {taskinstance.py:2889} INFO - Executing <Task(DockerOperator): t2> on 2024-12-20 17:37:06.900846+00:00
[2024-12-20T17:37:24.162+0000] {warnings.py:112} WARNING - /home/***/.local/lib/python3.12/site-packages/***/task/task_runner/standard_task_runner.py:70: DeprecationWarning: This process (pid=1168) is multi-threaded, use of fork() may lead to deadlocks in the child.
  pid = os.fork()

[2024-12-20T17:37:24.165+0000] {standard_task_runner.py:72} INFO - Started process 1169 to run task
[2024-12-20T17:37:24.166+0000] {standard_task_runner.py:104} INFO - Running: ['***', 'tasks', 'run', 'docker_dag', 't2', 'manual__2024-12-20T17:37:06.900846+00:00', '--job-id', '60', '--raw', '--subdir', 'DAGS_FOLDER/A_dag_test.py', '--cfg-path', '/tmp/tmpr5onfc2h']
[2024-12-20T17:37:24.167+0000] {standard_task_runner.py:105} INFO - Job 60: Subtask t2
[2024-12-20T17:37:24.218+0000] {task_command.py:467} INFO - Running <TaskInstance: docker_dag.t2 manual__2024-12-20T17:37:06.900846+00:00 [running]> on host 6cb319c12099
[2024-12-20T17:37:24.263+0000] {taskinstance.py:3132} INFO - Exporting env vars: AIRFLOW_CTX_DAG_OWNER='***' AIRFLOW_CTX_DAG_ID='docker_dag' AIRFLOW_CTX_TASK_ID='t2' AIRFLOW_CTX_EXECUTION_DATE='2024-12-20T17:37:06.900846+00:00' AIRFLOW_CTX_TRY_NUMBER='1' AIRFLOW_CTX_DAG_RUN_ID='manual__2024-12-20T17:37:06.900846+00:00'
[2024-12-20T17:37:24.264+0000] {logging_mixin.py:190} INFO - Task instance is in running state
[2024-12-20T17:37:24.264+0000] {logging_mixin.py:190} INFO -  Previous state of the Task instance: queued
[2024-12-20T17:37:24.264+0000] {logging_mixin.py:190} INFO - Current task name:t2 state:running start_date:2024-12-20 17:37:24.094910+00:00
[2024-12-20T17:37:24.264+0000] {logging_mixin.py:190} INFO - Dag name:docker_dag and current dag run status:running
[2024-12-20T17:37:24.264+0000] {taskinstance.py:731} INFO - ::endgroup::
[2024-12-20T17:37:24.505+0000] {docker.py:379} INFO - Starting docker container from image spark-cluster:version-1.0.0
[2024-12-20T17:37:24.551+0000] {docker.py:387} WARNING - Using remote engine or docker-in-docker and mounting temporary volume from host is not supported. Falling back to `mount_tmp_dir=False` mode. You can set `mount_tmp_dir` parameter to False to disable mounting and remove the warning
[2024-12-20T17:37:26.921+0000] {docker.py:73} INFO - Input Notebook:  /home/jovyan/Notebooks/NB_Calendar.ipynb
[2024-12-20T17:37:26.925+0000] {docker.py:73} INFO - Output Notebook: /home/jovyan/Notebooks/output/NB_Calendar.ipynb
[2024-12-20T17:37:26.989+0000] {docker.py:73} INFO - Executing:   0%|          | 0/14 [00:00<?, ?cell/s]
[2024-12-20T17:37:27.016+0000] {docker.py:73} INFO - Traceback (most recent call last):
[2024-12-20T17:37:27.017+0000] {docker.py:73} INFO -   File "/opt/conda/bin/papermill", line 8, in <module>
[2024-12-20T17:37:27.018+0000] {docker.py:73} INFO -     sys.exit(papermill())
[2024-12-20T17:37:27.018+0000] {docker.py:73} INFO -              ^^^^^^^^^^^
[2024-12-20T17:37:27.019+0000] {docker.py:73} INFO -   File "/opt/conda/lib/python3.11/site-packages/click/core.py", line 1157, in __call__
[2024-12-20T17:37:27.019+0000] {docker.py:73} INFO -     return self.main(*args, **kwargs)
[2024-12-20T17:37:27.020+0000] {docker.py:73} INFO -            ^^^^^^^^^^^^^^^^^^^^^^^^^^
[2024-12-20T17:37:27.020+0000] {docker.py:73} INFO -   File "/opt/conda/lib/python3.11/site-packages/click/core.py", line 1078, in main
[2024-12-20T17:37:27.020+0000] {docker.py:73} INFO -     rv = self.invoke(ctx)
[2024-12-20T17:37:27.021+0000] {docker.py:73} INFO -          ^^^^^^^^^^^^^^^^
[2024-12-20T17:37:27.021+0000] {docker.py:73} INFO -   File "/opt/conda/lib/python3.11/site-packages/click/core.py", line 1434, in invoke
[2024-12-20T17:37:27.021+0000] {docker.py:73} INFO -     return ctx.invoke(self.callback, **ctx.params)
[2024-12-20T17:37:27.021+0000] {docker.py:73} INFO -            ^^^^^^^^^^^^^^^^^^^^^^^^^^^^^^^^^^^^^^^
[2024-12-20T17:37:27.021+0000] {docker.py:73} INFO -   File "/opt/conda/lib/python3.11/site-packages/click/core.py", line 783, in invoke
[2024-12-20T17:37:27.021+0000] {docker.py:73} INFO -     return __callback(*args, **kwargs)
[2024-12-20T17:37:27.022+0000] {docker.py:73} INFO -            ^^^^^^^^^^^^^^^^^^^^^^^^^^^
[2024-12-20T17:37:27.022+0000] {docker.py:73} INFO -   File "/opt/conda/lib/python3.11/site-packages/click/decorators.py", line 33, in new_func
[2024-12-20T17:37:27.022+0000] {docker.py:73} INFO -     return f(get_current_context(), *args, **kwargs)
[2024-12-20T17:37:27.022+0000] {docker.py:73} INFO -            ^^^^^^^^^^^^^^^^^^^^^^^^^^^^^^^^^^^^^^^^^
[2024-12-20T17:37:27.022+0000] {docker.py:73} INFO -   File "/opt/conda/lib/python3.11/site-packages/papermill/cli.py", line 235, in papermill
[2024-12-20T17:37:27.022+0000] {docker.py:73} INFO -     execute_notebook(
[2024-12-20T17:37:27.022+0000] {docker.py:73} INFO -   File "/opt/conda/lib/python3.11/site-packages/papermill/execute.py", line 116, in execute_notebook
[2024-12-20T17:37:27.023+0000] {docker.py:73} INFO -     nb = papermill_engines.execute_notebook_with_engine(
[2024-12-20T17:37:27.023+0000] {docker.py:73} INFO -          ^^^^^^^^^^^^^^^^^^^^^^^^^^^^^^^^^^^^^^^^^^^^^^^
[2024-12-20T17:37:27.023+0000] {docker.py:73} INFO -   File "/opt/conda/lib/python3.11/site-packages/papermill/engines.py", line 48, in execute_notebook_with_engine
[2024-12-20T17:37:27.023+0000] {docker.py:73} INFO -     return self.get_engine(engine_name).execute_notebook(nb, kernel_name, **kwargs)
[2024-12-20T17:37:27.023+0000] {docker.py:73} INFO -            ^^^^^^^^^^^^^^^^^^^^^^^^^^^^^^^^^^^^^^^^^^^^^^^^^^^^^^^^^^^^^^^^^^^^^^^^
[2024-12-20T17:37:27.023+0000] {docker.py:73} INFO -   File "/opt/conda/lib/python3.11/site-packages/papermill/engines.py", line 368, in execute_notebook
[2024-12-20T17:37:27.023+0000] {docker.py:73} INFO -     nb_man.notebook_start()
[2024-12-20T17:37:27.024+0000] {docker.py:73} INFO -   File "/opt/conda/lib/python3.11/site-packages/papermill/engines.py", line 76, in wrapper
[2024-12-20T17:37:27.024+0000] {docker.py:73} INFO -     return func(self, *args, **kwargs)
[2024-12-20T17:37:27.024+0000] {docker.py:73} INFO -            ^^^^^^^^^^^^^^^^^^^^^^^^^^^
[2024-12-20T17:37:27.024+0000] {docker.py:73} INFO -   File "/opt/conda/lib/python3.11/site-packages/papermill/engines.py", line 211, in notebook_start
[2024-12-20T17:37:27.024+0000] {docker.py:73} INFO -     self.save()
[2024-12-20T17:37:27.024+0000] {docker.py:73} INFO -   File "/opt/conda/lib/python3.11/site-packages/papermill/engines.py", line 76, in wrapper
[2024-12-20T17:37:27.024+0000] {docker.py:73} INFO -     return func(self, *args, **kwargs)
[2024-12-20T17:37:27.025+0000] {docker.py:73} INFO -            ^^^^^^^^^^^^^^^^^^^^^^^^^^^
[2024-12-20T17:37:27.025+0000] {docker.py:73} INFO -   File "/opt/conda/lib/python3.11/site-packages/papermill/engines.py", line 152, in save
[2024-12-20T17:37:27.025+0000] {docker.py:73} INFO -     write_ipynb(self.nb, self.output_path)
[2024-12-20T17:37:27.025+0000] {docker.py:73} INFO -   File "/opt/conda/lib/python3.11/site-packages/papermill/iorw.py", line 486, in write_ipynb
[2024-12-20T17:37:27.025+0000] {docker.py:73} INFO -     papermill_io.write(nbformat.writes(nb), path)
[2024-12-20T17:37:27.025+0000] {docker.py:73} INFO -   File "/opt/conda/lib/python3.11/site-packages/papermill/iorw.py", line 102, in write
[2024-12-20T17:37:27.025+0000] {docker.py:73} INFO -     return self.get_handler(path, extensions).write(buf, path)
[2024-12-20T17:37:27.025+0000] {docker.py:73} INFO -            ^^^^^^^^^^^^^^^^^^^^^^^^^^^^^^^^^^^^^^^^^^^^^^^^^^^
[2024-12-20T17:37:27.026+0000] {docker.py:73} INFO -   File "/opt/conda/lib/python3.11/site-packages/papermill/iorw.py", line 214, in write
[2024-12-20T17:37:27.026+0000] {docker.py:73} INFO -     with open(path, 'w', encoding="utf-8") as f:
[2024-12-20T17:37:27.026+0000] {docker.py:73} INFO -          ^^^^^^^^^^^^^^^^^^^^^^^^^^^^^^^^^
[2024-12-20T17:37:27.026+0000] {docker.py:73} INFO - PermissionError: [Errno 13] Permission denied: '/home/jovyan/Notebooks/output/NB_Calendar.ipynb'
[2024-12-20T17:37:27.038+0000] {docker.py:73} INFO - Executing:   0%|          | 0/14 [00:00<?, ?cell/s]
[2024-12-20T17:37:27.513+0000] {taskinstance.py:3311} ERROR - Task failed with exception
Traceback (most recent call last):
  File "/home/airflow/.local/lib/python3.12/site-packages/docker/api/client.py", line 275, in _raise_for_status
    response.raise_for_status()
  File "/home/airflow/.local/lib/python3.12/site-packages/requests/models.py", line 1024, in raise_for_status
    raise HTTPError(http_error_msg, response=self)
requests.exceptions.HTTPError: 400 Client Error: Bad Request for url: http+docker://localhost/v1.47/containers/create

The above exception was the direct cause of the following exception:

Traceback (most recent call last):
  File "/home/airflow/.local/lib/python3.12/site-packages/airflow/providers/docker/operators/docker.py", line 384, in _run_image
    return self._run_image_with_mounts([*self.mounts, tmp_mount], add_tmp_variable=True)
           ^^^^^^^^^^^^^^^^^^^^^^^^^^^^^^^^^^^^^^^^^^^^^^^^^^^^^^^^^^^^^^^^^^^^^^^^^^^^^
  File "/home/airflow/.local/lib/python3.12/site-packages/airflow/providers/docker/operators/docker.py", line 411, in _run_image_with_mounts
    self.container = self.cli.create_container(
                     ^^^^^^^^^^^^^^^^^^^^^^^^^^
  File "/home/airflow/.local/lib/python3.12/site-packages/docker/api/container.py", line 440, in create_container
    return self.create_container_from_config(config, name, platform)
           ^^^^^^^^^^^^^^^^^^^^^^^^^^^^^^^^^^^^^^^^^^^^^^^^^^^^^^^^^
  File "/home/airflow/.local/lib/python3.12/site-packages/docker/api/container.py", line 457, in create_container_from_config
    return self._result(res, True)
           ^^^^^^^^^^^^^^^^^^^^^^^
  File "/home/airflow/.local/lib/python3.12/site-packages/docker/api/client.py", line 281, in _result
    self._raise_for_status(response)
  File "/home/airflow/.local/lib/python3.12/site-packages/docker/api/client.py", line 277, in _raise_for_status
    raise create_api_error_from_http_exception(e) from e
          ^^^^^^^^^^^^^^^^^^^^^^^^^^^^^^^^^^^^^^^
  File "/home/airflow/.local/lib/python3.12/site-packages/docker/errors.py", line 39, in create_api_error_from_http_exception
    raise cls(e, response=response, explanation=explanation) from e
docker.errors.APIError: 400 Client Error for http+docker://localhost/v1.47/containers/create: Bad Request ("invalid mount config for type "bind": bind source path does not exist: /host_mnt/private/tmp/airflowtmpy3hdndg4")

During handling of the above exception, another exception occurred:

Traceback (most recent call last):
  File "/home/airflow/.local/lib/python3.12/site-packages/airflow/models/taskinstance.py", line 767, in _execute_task
    result = _execute_callable(context=context, **execute_callable_kwargs)
             ^^^^^^^^^^^^^^^^^^^^^^^^^^^^^^^^^^^^^^^^^^^^^^^^^^^^^^^^^^^^^
  File "/home/airflow/.local/lib/python3.12/site-packages/airflow/models/taskinstance.py", line 733, in _execute_callable
    return ExecutionCallableRunner(
           ^^^^^^^^^^^^^^^^^^^^^^^^
  File "/home/airflow/.local/lib/python3.12/site-packages/airflow/utils/operator_helpers.py", line 252, in run
    return self.func(*args, **kwargs)
           ^^^^^^^^^^^^^^^^^^^^^^^^^^
  File "/home/airflow/.local/lib/python3.12/site-packages/airflow/models/baseoperator.py", line 422, in wrapper
    return func(self, *args, **kwargs)
           ^^^^^^^^^^^^^^^^^^^^^^^^^^^
  File "/home/airflow/.local/lib/python3.12/site-packages/airflow/providers/docker/operators/docker.py", line 519, in execute
    return self._run_image()
           ^^^^^^^^^^^^^^^^^
  File "/home/airflow/.local/lib/python3.12/site-packages/airflow/providers/docker/operators/docker.py", line 393, in _run_image
    return self._run_image_with_mounts(self.mounts, add_tmp_variable=False)
           ^^^^^^^^^^^^^^^^^^^^^^^^^^^^^^^^^^^^^^^^^^^^^^^^^^^^^^^^^^^^^^^^
  File "/home/airflow/.local/lib/python3.12/site-packages/airflow/providers/docker/operators/docker.py", line 453, in _run_image_with_mounts
    raise DockerContainerFailedException(f"Docker container failed: {result!r}", logs=log_lines)
airflow.providers.docker.exceptions.DockerContainerFailedException: Docker container failed: {'StatusCode': 1}
[2024-12-20T17:37:27.563+0000] {logging_mixin.py:190} INFO - Task instance in failure state
[2024-12-20T17:37:27.564+0000] {logging_mixin.py:190} INFO - Task start:2024-12-20 17:37:24.094910+00:00 end:2024-12-20 17:37:27.538547+00:00 duration:3.443637
[2024-12-20T17:37:27.566+0000] {logging_mixin.py:190} INFO - Task:<Task(DockerOperator): t2> dag:<DAG: docker_dag> dagrun:<DagRun docker_dag @ 2024-12-20 17:37:06.900846+00:00: manual__2024-12-20T17:37:06.900846+00:00, state:running, queued_at: 2024-12-20 17:37:06.943373+00:00. externally triggered: True>
[2024-12-20T17:37:27.566+0000] {logging_mixin.py:190} INFO - Failure caused by Docker container failed: {'StatusCode': 1}
[2024-12-20T17:37:27.567+0000] {taskinstance.py:1225} INFO - Marking task as FAILED. dag_id=docker_dag, task_id=t2, run_id=manual__2024-12-20T17:37:06.900846+00:00, execution_date=20241220T173706, start_date=20241220T173724, end_date=20241220T173727
[2024-12-20T17:37:27.600+0000] {taskinstance.py:340} INFO - ::group::Post task execution logs
[2024-12-20T17:37:27.601+0000] {standard_task_runner.py:124} ERROR - Failed to execute job 60 for task t2 (Docker container failed: {'StatusCode': 1}; 1169)
Traceback (most recent call last):
  File "/home/airflow/.local/lib/python3.12/site-packages/docker/api/client.py", line 275, in _raise_for_status
    response.raise_for_status()
  File "/home/airflow/.local/lib/python3.12/site-packages/requests/models.py", line 1024, in raise_for_status
    raise HTTPError(http_error_msg, response=self)
requests.exceptions.HTTPError: 400 Client Error: Bad Request for url: http+docker://localhost/v1.47/containers/create

The above exception was the direct cause of the following exception:

Traceback (most recent call last):
  File "/home/airflow/.local/lib/python3.12/site-packages/airflow/providers/docker/operators/docker.py", line 384, in _run_image
    return self._run_image_with_mounts([*self.mounts, tmp_mount], add_tmp_variable=True)
           ^^^^^^^^^^^^^^^^^^^^^^^^^^^^^^^^^^^^^^^^^^^^^^^^^^^^^^^^^^^^^^^^^^^^^^^^^^^^^
  File "/home/airflow/.local/lib/python3.12/site-packages/airflow/providers/docker/operators/docker.py", line 411, in _run_image_with_mounts
    self.container = self.cli.create_container(
                     ^^^^^^^^^^^^^^^^^^^^^^^^^^
  File "/home/airflow/.local/lib/python3.12/site-packages/docker/api/container.py", line 440, in create_container
    return self.create_container_from_config(config, name, platform)
           ^^^^^^^^^^^^^^^^^^^^^^^^^^^^^^^^^^^^^^^^^^^^^^^^^^^^^^^^^
  File "/home/airflow/.local/lib/python3.12/site-packages/docker/api/container.py", line 457, in create_container_from_config
    return self._result(res, True)
           ^^^^^^^^^^^^^^^^^^^^^^^
  File "/home/airflow/.local/lib/python3.12/site-packages/docker/api/client.py", line 281, in _result
    self._raise_for_status(response)
  File "/home/airflow/.local/lib/python3.12/site-packages/docker/api/client.py", line 277, in _raise_for_status
    raise create_api_error_from_http_exception(e) from e
          ^^^^^^^^^^^^^^^^^^^^^^^^^^^^^^^^^^^^^^^
  File "/home/airflow/.local/lib/python3.12/site-packages/docker/errors.py", line 39, in create_api_error_from_http_exception
    raise cls(e, response=response, explanation=explanation) from e
docker.errors.APIError: 400 Client Error for http+docker://localhost/v1.47/containers/create: Bad Request ("invalid mount config for type "bind": bind source path does not exist: /host_mnt/private/tmp/airflowtmpy3hdndg4")

During handling of the above exception, another exception occurred:

Traceback (most recent call last):
  File "/home/airflow/.local/lib/python3.12/site-packages/airflow/task/task_runner/standard_task_runner.py", line 117, in _start_by_fork
    ret = args.func(args, dag=self.dag)
          ^^^^^^^^^^^^^^^^^^^^^^^^^^^^^
  File "/home/airflow/.local/lib/python3.12/site-packages/airflow/cli/cli_config.py", line 49, in command
    return func(*args, **kwargs)
           ^^^^^^^^^^^^^^^^^^^^^
  File "/home/airflow/.local/lib/python3.12/site-packages/airflow/utils/cli.py", line 116, in wrapper
    return f(*args, **kwargs)
           ^^^^^^^^^^^^^^^^^^
  File "/home/airflow/.local/lib/python3.12/site-packages/airflow/cli/commands/task_command.py", line 483, in task_run
    task_return_code = _run_task_by_selected_method(args, _dag, ti)
                       ^^^^^^^^^^^^^^^^^^^^^^^^^^^^^^^^^^^^^^^^^^^^
  File "/home/airflow/.local/lib/python3.12/site-packages/airflow/cli/commands/task_command.py", line 256, in _run_task_by_selected_method
    return _run_raw_task(args, ti)
           ^^^^^^^^^^^^^^^^^^^^^^^
  File "/home/airflow/.local/lib/python3.12/site-packages/airflow/cli/commands/task_command.py", line 341, in _run_raw_task
    return ti._run_raw_task(
           ^^^^^^^^^^^^^^^^^
  File "/home/airflow/.local/lib/python3.12/site-packages/airflow/utils/session.py", line 97, in wrapper
    return func(*args, session=session, **kwargs)
           ^^^^^^^^^^^^^^^^^^^^^^^^^^^^^^^^^^^^^^
  File "/home/airflow/.local/lib/python3.12/site-packages/airflow/models/taskinstance.py", line 3005, in _run_raw_task
    return _run_raw_task(
           ^^^^^^^^^^^^^^
  File "/home/airflow/.local/lib/python3.12/site-packages/airflow/models/taskinstance.py", line 273, in _run_raw_task
    TaskInstance._execute_task_with_callbacks(
  File "/home/airflow/.local/lib/python3.12/site-packages/airflow/models/taskinstance.py", line 3159, in _execute_task_with_callbacks
    result = self._execute_task(context, task_orig)
             ^^^^^^^^^^^^^^^^^^^^^^^^^^^^^^^^^^^^^^
  File "/home/airflow/.local/lib/python3.12/site-packages/airflow/models/taskinstance.py", line 3183, in _execute_task
    return _execute_task(self, context, task_orig)
           ^^^^^^^^^^^^^^^^^^^^^^^^^^^^^^^^^^^^^^^
  File "/home/airflow/.local/lib/python3.12/site-packages/airflow/models/taskinstance.py", line 767, in _execute_task
    result = _execute_callable(context=context, **execute_callable_kwargs)
             ^^^^^^^^^^^^^^^^^^^^^^^^^^^^^^^^^^^^^^^^^^^^^^^^^^^^^^^^^^^^^
  File "/home/airflow/.local/lib/python3.12/site-packages/airflow/models/taskinstance.py", line 733, in _execute_callable
    return ExecutionCallableRunner(
           ^^^^^^^^^^^^^^^^^^^^^^^^
  File "/home/airflow/.local/lib/python3.12/site-packages/airflow/utils/operator_helpers.py", line 252, in run
    return self.func(*args, **kwargs)
           ^^^^^^^^^^^^^^^^^^^^^^^^^^
  File "/home/airflow/.local/lib/python3.12/site-packages/airflow/models/baseoperator.py", line 422, in wrapper
    return func(self, *args, **kwargs)
           ^^^^^^^^^^^^^^^^^^^^^^^^^^^
  File "/home/airflow/.local/lib/python3.12/site-packages/airflow/providers/docker/operators/docker.py", line 519, in execute
    return self._run_image()
           ^^^^^^^^^^^^^^^^^
  File "/home/airflow/.local/lib/python3.12/site-packages/airflow/providers/docker/operators/docker.py", line 393, in _run_image
    return self._run_image_with_mounts(self.mounts, add_tmp_variable=False)
           ^^^^^^^^^^^^^^^^^^^^^^^^^^^^^^^^^^^^^^^^^^^^^^^^^^^^^^^^^^^^^^^^
  File "/home/airflow/.local/lib/python3.12/site-packages/airflow/providers/docker/operators/docker.py", line 453, in _run_image_with_mounts
    raise DockerContainerFailedException(f"Docker container failed: {result!r}", logs=log_lines)
airflow.providers.docker.exceptions.DockerContainerFailedException: Docker container failed: {'StatusCode': 1}
[2024-12-20T17:37:27.645+0000] {local_task_job_runner.py:266} INFO - Task exited with return code 1
[2024-12-20T17:37:27.692+0000] {taskinstance.py:3895} INFO - 0 downstream tasks scheduled from follow-on schedule check
[2024-12-20T17:37:27.694+0000] {local_task_job_runner.py:245} INFO - ::endgroup::
