[2024-12-23T09:34:21.406+0000] {local_task_job_runner.py:123} INFO - ::group::Pre task execution logs
[2024-12-23T09:34:21.442+0000] {taskinstance.py:2613} INFO - Dependencies all met for dep_context=non-requeueable deps ti=<TaskInstance: dag_Calendar_NTBK.Notebook_job scheduled__2024-12-22T00:00:00+00:00 [queued]>
[2024-12-23T09:34:21.454+0000] {taskinstance.py:2613} INFO - Dependencies all met for dep_context=requeueable deps ti=<TaskInstance: dag_Calendar_NTBK.Notebook_job scheduled__2024-12-22T00:00:00+00:00 [queued]>
[2024-12-23T09:34:21.456+0000] {taskinstance.py:2866} INFO - Starting attempt 1 of 1
[2024-12-23T09:34:21.474+0000] {taskinstance.py:2889} INFO - Executing <Task(DockerOperator): Notebook_job> on 2024-12-22 00:00:00+00:00
[2024-12-23T09:34:21.506+0000] {standard_task_runner.py:104} INFO - Running: ['***', 'tasks', 'run', 'dag_Calendar_NTBK', 'Notebook_job', 'scheduled__2024-12-22T00:00:00+00:00', '--job-id', '208', '--raw', '--subdir', 'DAGS_FOLDER/A_dag_test.py', '--cfg-path', '/tmp/tmpfsg7uyhc']
[2024-12-23T09:34:21.501+0000] {warnings.py:112} WARNING - /home/***/.local/lib/python3.12/site-packages/***/task/task_runner/standard_task_runner.py:70: DeprecationWarning: This process (pid=117) is multi-threaded, use of fork() may lead to deadlocks in the child.
  pid = os.fork()

[2024-12-23T09:34:21.509+0000] {standard_task_runner.py:105} INFO - Job 208: Subtask Notebook_job
[2024-12-23T09:34:21.509+0000] {standard_task_runner.py:72} INFO - Started process 119 to run task
[2024-12-23T09:34:21.645+0000] {task_command.py:467} INFO - Running <TaskInstance: dag_Calendar_NTBK.Notebook_job scheduled__2024-12-22T00:00:00+00:00 [running]> on host 85f5ad808200
[2024-12-23T09:34:21.770+0000] {taskinstance.py:3132} INFO - Exporting env vars: AIRFLOW_CTX_DAG_OWNER='***' AIRFLOW_CTX_DAG_ID='dag_Calendar_NTBK' AIRFLOW_CTX_TASK_ID='Notebook_job' AIRFLOW_CTX_EXECUTION_DATE='2024-12-22T00:00:00+00:00' AIRFLOW_CTX_TRY_NUMBER='1' AIRFLOW_CTX_DAG_RUN_ID='scheduled__2024-12-22T00:00:00+00:00'
[2024-12-23T09:34:21.772+0000] {taskinstance.py:731} INFO - ::endgroup::
[2024-12-23T09:34:22.053+0000] {docker.py:379} INFO - Starting docker container from image spark-cluster:version-1.0.0
[2024-12-23T09:34:24.382+0000] {docker.py:73} INFO - Input Notebook:  /home/jovyan/Notebooks/NB_Calendar.ipynb
[2024-12-23T09:34:24.393+0000] {docker.py:73} INFO - Output Notebook: /home/jovyan/Notebooks/output-NB_Calendar.ipynb
[2024-12-23T09:34:24.720+0000] {docker.py:73} INFO - Executing:   0%|          | 0/14 [00:00<?, ?cell/s]
[2024-12-23T09:34:27.405+0000] {docker.py:73} INFO - Executing notebook with kernel: python3
[2024-12-23T09:34:29.388+0000] {docker.py:73} INFO - Executing:   7%|▋         | 1/14 [00:04<01:00,  4.66s/cell]
[2024-12-23T09:34:32.494+0000] {docker.py:73} INFO - :: loading settings :: url = jar:file:/usr/local/spark/jars/ivy-2.5.1.jar!/org/apache/ivy/core/settings/ivysettings.xml
[2024-12-23T09:34:32.564+0000] {docker.py:73} INFO - Ivy Default Cache set to: /home/jovyan/.ivy2/cache
[2024-12-23T09:34:32.565+0000] {docker.py:73} INFO - The jars for the packages stored in: /home/jovyan/.ivy2/jars
[2024-12-23T09:34:32.569+0000] {docker.py:73} INFO - io.delta#delta-spark_2.12 added as a dependency
[2024-12-23T09:34:32.570+0000] {docker.py:73} INFO - :: resolving dependencies :: org.apache.spark#spark-submit-parent-b20b2d1a-b9cf-4604-88f8-629189a4f35b;1.0
[2024-12-23T09:34:32.570+0000] {docker.py:73} INFO - 	confs: [default]
[2024-12-23T09:34:42.683+0000] {docker.py:73} INFO - 	found io.delta#delta-spark_2.12;3.1.0 in central
[2024-12-23T09:34:42.709+0000] {docker.py:73} INFO - downloading https://repo1.maven.org/maven2/io/delta/delta-spark_2.12/3.1.0/delta-spark_2.12-3.1.0.jar ...
[2024-12-23T09:35:07.975+0000] {docker.py:73} INFO - 	[SUCCESSFUL ] io.delta#delta-spark_2.12;3.1.0!delta-spark_2.12.jar (25232ms)
[2024-12-23T09:35:08.019+0000] {docker.py:73} INFO - :: resolution report :: resolve 10136ms :: artifacts dl 25271ms
[2024-12-23T09:35:08.021+0000] {docker.py:73} INFO - 	:: modules in use:
[2024-12-23T09:35:08.026+0000] {docker.py:73} INFO - 	io.delta#delta-spark_2.12;3.1.0 from central in [default]
[2024-12-23T09:35:08.028+0000] {docker.py:73} INFO - 	---------------------------------------------------------------------
[2024-12-23T09:35:08.033+0000] {docker.py:73} INFO - 	|                  |            modules            ||   artifacts   |
[2024-12-23T09:35:08.035+0000] {docker.py:73} INFO - 	|       conf       | number| search|dwnlded|evicted|| number|dwnlded|
[2024-12-23T09:35:08.035+0000] {docker.py:73} INFO - 	---------------------------------------------------------------------
[2024-12-23T09:35:08.036+0000] {docker.py:73} INFO - 	|      default     |   1   |   1   |   0   |   0   ||   1   |   1   |
[2024-12-23T09:35:08.037+0000] {docker.py:73} INFO - 	---------------------------------------------------------------------
[2024-12-23T09:35:08.099+0000] {docker.py:73} INFO - 
[2024-12-23T09:35:08.103+0000] {docker.py:73} INFO - :: problems summary ::
[2024-12-23T09:35:08.106+0000] {docker.py:73} INFO - :::: ERRORS
[2024-12-23T09:35:08.108+0000] {docker.py:73} INFO - 	Server access error at url https://repo1.maven.org/maven2/io/delta/delta-spark_2.12/3.1.0/delta-spark_2.12-3.1.0.pom (java.net.ConnectException: Connection refused)
[2024-12-23T09:35:08.113+0000] {docker.py:73} INFO - 
[2024-12-23T09:35:08.116+0000] {docker.py:73} INFO - 
[2024-12-23T09:35:08.117+0000] {docker.py:73} INFO - :: USE VERBOSE OR DEBUG MESSAGE LEVEL FOR MORE DETAILS
[2024-12-23T09:35:08.119+0000] {docker.py:73} INFO - :: retrieving :: org.apache.spark#spark-submit-parent-b20b2d1a-b9cf-4604-88f8-629189a4f35b
[2024-12-23T09:35:08.120+0000] {docker.py:73} INFO - 	confs: [default]
[2024-12-23T09:35:08.267+0000] {docker.py:73} INFO - 	1 artifacts copied, 0 already retrieved (5374kB/145ms)
[2024-12-23T09:35:10.030+0000] {docker.py:73} INFO - 24/12/23 09:35:09 WARN NativeCodeLoader: Unable to load native-hadoop library for your platform... using builtin-java classes where applicable
[2024-12-23T09:35:12.480+0000] {docker.py:73} INFO - Setting default log level to "WARN".
[2024-12-23T09:35:12.507+0000] {docker.py:73} INFO - To adjust logging level use sc.setLogLevel(newLevel). For SparkR, use setLogLevel(newLevel).
[2024-12-23T09:35:16.159+0000] {docker.py:73} INFO - 24/12/23 09:35:16 WARN StandaloneSchedulerBackend: Dynamic allocation enabled without spark.executor.cores explicitly set, you may get more executors allocated than expected. It's recommended to set spark.executor.cores explicitly. Please check SPARK-30299 for more details.
[2024-12-23T09:35:17.832+0000] {docker.py:73} INFO - 24/12/23 09:35:17 WARN Utils: spark.executor.instances less than spark.dynamicAllocation.minExecutors is invalid, ignoring its setting, please update your configs.
[2024-12-23T09:35:26.166+0000] {docker.py:73} INFO - Executing:  21%|██▏       | 3/14 [01:01<04:04, 22.23s/cell]
[2024-12-23T09:35:26.276+0000] {docker.py:73} INFO - Executing:  36%|███▌      | 5/14 [01:01<01:37, 10.84s/cell]
[2024-12-23T09:35:34.614+0000] {docker.py:73} INFO - Executing:  43%|████▎     | 6/14 [01:09<01:21, 10.16s/cell]
[2024-12-23T09:35:35.623+0000] {docker.py:73} INFO - Executing:  50%|█████     | 7/14 [01:10<00:53,  7.62s/cell]
[2024-12-23T09:35:36.309+0000] {docker.py:73} INFO - Executing:  57%|█████▋    | 8/14 [01:11<00:33,  5.66s/cell]
[2024-12-23T09:35:39.160+0000] {docker.py:73} INFO - 24/12/23 09:35:39 WARN StandaloneAppClient$ClientEndpoint: Connection to 172.19.0.3:7077 failed; waiting for master to reconnect...
[2024-12-23T09:35:39.185+0000] {docker.py:73} INFO - 24/12/23 09:35:39 WARN StandaloneSchedulerBackend: Disconnected from Spark cluster! Waiting for reconnection...
[2024-12-23T09:35:42.675+0000] {docker.py:73} INFO - [Stage 0:>                                                          (0 + 0) / 2]
[2024-12-23T09:35:57.355+0000] {docker.py:73} INFO - 24/12/23 09:35:57 WARN TaskSchedulerImpl: Initial job has not accepted any resources; check your cluster UI to ensure that workers are registered and have sufficient resources
[2024-12-23T09:36:12.352+0000] {docker.py:73} INFO - 24/12/23 09:36:12 WARN TaskSchedulerImpl: Initial job has not accepted any resources; check your cluster UI to ensure that workers are registered and have sufficient resources
[2024-12-23T09:36:27.357+0000] {docker.py:73} INFO - 24/12/23 09:36:27 WARN TaskSchedulerImpl: Initial job has not accepted any resources; check your cluster UI to ensure that workers are registered and have sufficient resources
[2024-12-23T09:36:30.764+0000] {taskinstance.py:3311} ERROR - Task failed with exception
Traceback (most recent call last):
  File "/home/airflow/.local/lib/python3.12/site-packages/airflow/providers/docker/operators/docker.py", line 453, in _run_image_with_mounts
    raise DockerContainerFailedException(f"Docker container failed: {result!r}", logs=log_lines)
airflow.providers.docker.exceptions.DockerContainerFailedException: Docker container failed: {'StatusCode': 137}

During handling of the above exception, another exception occurred:

Traceback (most recent call last):
  File "/home/airflow/.local/lib/python3.12/site-packages/docker/api/client.py", line 275, in _raise_for_status
    response.raise_for_status()
  File "/home/airflow/.local/lib/python3.12/site-packages/requests/models.py", line 1024, in raise_for_status
    raise HTTPError(http_error_msg, response=self)
requests.exceptions.HTTPError: 409 Client Error: Conflict for url: http+docker://localhost/v1.47/containers/e1120187ab0948c850039a8d7560d269d83533f7e953036fc5ace4b7258882b0?v=False&link=False&force=False

The above exception was the direct cause of the following exception:

Traceback (most recent call last):
  File "/home/airflow/.local/lib/python3.12/site-packages/airflow/models/taskinstance.py", line 767, in _execute_task
    result = _execute_callable(context=context, **execute_callable_kwargs)
             ^^^^^^^^^^^^^^^^^^^^^^^^^^^^^^^^^^^^^^^^^^^^^^^^^^^^^^^^^^^^^
  File "/home/airflow/.local/lib/python3.12/site-packages/airflow/models/taskinstance.py", line 733, in _execute_callable
    return ExecutionCallableRunner(
           ^^^^^^^^^^^^^^^^^^^^^^^^
  File "/home/airflow/.local/lib/python3.12/site-packages/airflow/utils/operator_helpers.py", line 252, in run
    return self.func(*args, **kwargs)
           ^^^^^^^^^^^^^^^^^^^^^^^^^^
  File "/home/airflow/.local/lib/python3.12/site-packages/airflow/models/baseoperator.py", line 422, in wrapper
    return func(self, *args, **kwargs)
           ^^^^^^^^^^^^^^^^^^^^^^^^^^^
  File "/home/airflow/.local/lib/python3.12/site-packages/airflow/providers/docker/operators/docker.py", line 519, in execute
    return self._run_image()
           ^^^^^^^^^^^^^^^^^
  File "/home/airflow/.local/lib/python3.12/site-packages/airflow/providers/docker/operators/docker.py", line 396, in _run_image
    return self._run_image_with_mounts(self.mounts, add_tmp_variable=False)
           ^^^^^^^^^^^^^^^^^^^^^^^^^^^^^^^^^^^^^^^^^^^^^^^^^^^^^^^^^^^^^^^^
  File "/home/airflow/.local/lib/python3.12/site-packages/airflow/providers/docker/operators/docker.py", line 471, in _run_image_with_mounts
    self.cli.remove_container(self.container["Id"])
  File "/home/airflow/.local/lib/python3.12/site-packages/docker/utils/decorators.py", line 19, in wrapped
    return f(self, resource_id, *args, **kwargs)
           ^^^^^^^^^^^^^^^^^^^^^^^^^^^^^^^^^^^^^
  File "/home/airflow/.local/lib/python3.12/site-packages/docker/api/container.py", line 1037, in remove_container
    self._raise_for_status(res)
  File "/home/airflow/.local/lib/python3.12/site-packages/docker/api/client.py", line 277, in _raise_for_status
    raise create_api_error_from_http_exception(e) from e
          ^^^^^^^^^^^^^^^^^^^^^^^^^^^^^^^^^^^^^^^
  File "/home/airflow/.local/lib/python3.12/site-packages/docker/errors.py", line 39, in create_api_error_from_http_exception
    raise cls(e, response=response, explanation=explanation) from e
docker.errors.APIError: 409 Client Error for http+docker://localhost/v1.47/containers/e1120187ab0948c850039a8d7560d269d83533f7e953036fc5ace4b7258882b0?v=False&link=False&force=False: Conflict ("removal of container e1120187ab0948c850039a8d7560d269d83533f7e953036fc5ace4b7258882b0 is already in progress")
[2024-12-23T09:36:30.815+0000] {taskinstance.py:1225} INFO - Marking task as FAILED. dag_id=dag_Calendar_NTBK, task_id=Notebook_job, run_id=scheduled__2024-12-22T00:00:00+00:00, execution_date=20241222T000000, start_date=20241223T093421, end_date=20241223T093630
[2024-12-23T09:36:30.841+0000] {taskinstance.py:340} INFO - ::group::Post task execution logs
[2024-12-23T09:36:30.843+0000] {standard_task_runner.py:124} ERROR - Failed to execute job 208 for task Notebook_job (409 Client Error for http+docker://localhost/v1.47/containers/e1120187ab0948c850039a8d7560d269d83533f7e953036fc5ace4b7258882b0?v=False&link=False&force=False: Conflict ("removal of container e1120187ab0948c850039a8d7560d269d83533f7e953036fc5ace4b7258882b0 is already in progress"); 119)
Traceback (most recent call last):
  File "/home/airflow/.local/lib/python3.12/site-packages/airflow/providers/docker/operators/docker.py", line 453, in _run_image_with_mounts
    raise DockerContainerFailedException(f"Docker container failed: {result!r}", logs=log_lines)
airflow.providers.docker.exceptions.DockerContainerFailedException: Docker container failed: {'StatusCode': 137}

During handling of the above exception, another exception occurred:

Traceback (most recent call last):
  File "/home/airflow/.local/lib/python3.12/site-packages/docker/api/client.py", line 275, in _raise_for_status
    response.raise_for_status()
  File "/home/airflow/.local/lib/python3.12/site-packages/requests/models.py", line 1024, in raise_for_status
    raise HTTPError(http_error_msg, response=self)
requests.exceptions.HTTPError: 409 Client Error: Conflict for url: http+docker://localhost/v1.47/containers/e1120187ab0948c850039a8d7560d269d83533f7e953036fc5ace4b7258882b0?v=False&link=False&force=False

The above exception was the direct cause of the following exception:

Traceback (most recent call last):
  File "/home/airflow/.local/lib/python3.12/site-packages/airflow/task/task_runner/standard_task_runner.py", line 117, in _start_by_fork
    ret = args.func(args, dag=self.dag)
          ^^^^^^^^^^^^^^^^^^^^^^^^^^^^^
  File "/home/airflow/.local/lib/python3.12/site-packages/airflow/cli/cli_config.py", line 49, in command
    return func(*args, **kwargs)
           ^^^^^^^^^^^^^^^^^^^^^
  File "/home/airflow/.local/lib/python3.12/site-packages/airflow/utils/cli.py", line 116, in wrapper
    return f(*args, **kwargs)
           ^^^^^^^^^^^^^^^^^^
  File "/home/airflow/.local/lib/python3.12/site-packages/airflow/cli/commands/task_command.py", line 483, in task_run
    task_return_code = _run_task_by_selected_method(args, _dag, ti)
                       ^^^^^^^^^^^^^^^^^^^^^^^^^^^^^^^^^^^^^^^^^^^^
  File "/home/airflow/.local/lib/python3.12/site-packages/airflow/cli/commands/task_command.py", line 256, in _run_task_by_selected_method
    return _run_raw_task(args, ti)
           ^^^^^^^^^^^^^^^^^^^^^^^
  File "/home/airflow/.local/lib/python3.12/site-packages/airflow/cli/commands/task_command.py", line 341, in _run_raw_task
    return ti._run_raw_task(
           ^^^^^^^^^^^^^^^^^
  File "/home/airflow/.local/lib/python3.12/site-packages/airflow/utils/session.py", line 97, in wrapper
    return func(*args, session=session, **kwargs)
           ^^^^^^^^^^^^^^^^^^^^^^^^^^^^^^^^^^^^^^
  File "/home/airflow/.local/lib/python3.12/site-packages/airflow/models/taskinstance.py", line 3005, in _run_raw_task
    return _run_raw_task(
           ^^^^^^^^^^^^^^
  File "/home/airflow/.local/lib/python3.12/site-packages/airflow/models/taskinstance.py", line 273, in _run_raw_task
    TaskInstance._execute_task_with_callbacks(
  File "/home/airflow/.local/lib/python3.12/site-packages/airflow/models/taskinstance.py", line 3159, in _execute_task_with_callbacks
    result = self._execute_task(context, task_orig)
             ^^^^^^^^^^^^^^^^^^^^^^^^^^^^^^^^^^^^^^
  File "/home/airflow/.local/lib/python3.12/site-packages/airflow/models/taskinstance.py", line 3183, in _execute_task
    return _execute_task(self, context, task_orig)
           ^^^^^^^^^^^^^^^^^^^^^^^^^^^^^^^^^^^^^^^
  File "/home/airflow/.local/lib/python3.12/site-packages/airflow/models/taskinstance.py", line 767, in _execute_task
    result = _execute_callable(context=context, **execute_callable_kwargs)
             ^^^^^^^^^^^^^^^^^^^^^^^^^^^^^^^^^^^^^^^^^^^^^^^^^^^^^^^^^^^^^
  File "/home/airflow/.local/lib/python3.12/site-packages/airflow/models/taskinstance.py", line 733, in _execute_callable
    return ExecutionCallableRunner(
           ^^^^^^^^^^^^^^^^^^^^^^^^
  File "/home/airflow/.local/lib/python3.12/site-packages/airflow/utils/operator_helpers.py", line 252, in run
    return self.func(*args, **kwargs)
           ^^^^^^^^^^^^^^^^^^^^^^^^^^
  File "/home/airflow/.local/lib/python3.12/site-packages/airflow/models/baseoperator.py", line 422, in wrapper
    return func(self, *args, **kwargs)
           ^^^^^^^^^^^^^^^^^^^^^^^^^^^
  File "/home/airflow/.local/lib/python3.12/site-packages/airflow/providers/docker/operators/docker.py", line 519, in execute
    return self._run_image()
           ^^^^^^^^^^^^^^^^^
  File "/home/airflow/.local/lib/python3.12/site-packages/airflow/providers/docker/operators/docker.py", line 396, in _run_image
    return self._run_image_with_mounts(self.mounts, add_tmp_variable=False)
           ^^^^^^^^^^^^^^^^^^^^^^^^^^^^^^^^^^^^^^^^^^^^^^^^^^^^^^^^^^^^^^^^
  File "/home/airflow/.local/lib/python3.12/site-packages/airflow/providers/docker/operators/docker.py", line 471, in _run_image_with_mounts
    self.cli.remove_container(self.container["Id"])
  File "/home/airflow/.local/lib/python3.12/site-packages/docker/utils/decorators.py", line 19, in wrapped
    return f(self, resource_id, *args, **kwargs)
           ^^^^^^^^^^^^^^^^^^^^^^^^^^^^^^^^^^^^^
  File "/home/airflow/.local/lib/python3.12/site-packages/docker/api/container.py", line 1037, in remove_container
    self._raise_for_status(res)
  File "/home/airflow/.local/lib/python3.12/site-packages/docker/api/client.py", line 277, in _raise_for_status
    raise create_api_error_from_http_exception(e) from e
          ^^^^^^^^^^^^^^^^^^^^^^^^^^^^^^^^^^^^^^^
  File "/home/airflow/.local/lib/python3.12/site-packages/docker/errors.py", line 39, in create_api_error_from_http_exception
    raise cls(e, response=response, explanation=explanation) from e
docker.errors.APIError: 409 Client Error for http+docker://localhost/v1.47/containers/e1120187ab0948c850039a8d7560d269d83533f7e953036fc5ace4b7258882b0?v=False&link=False&force=False: Conflict ("removal of container e1120187ab0948c850039a8d7560d269d83533f7e953036fc5ace4b7258882b0 is already in progress")
[2024-12-23T09:36:30.879+0000] {local_task_job_runner.py:266} INFO - Task exited with return code 1
[2024-12-23T09:36:30.904+0000] {taskinstance.py:3895} INFO - 0 downstream tasks scheduled from follow-on schedule check
[2024-12-23T09:36:30.905+0000] {local_task_job_runner.py:245} INFO - ::endgroup::
