[2024-12-24T05:23:22.921+0000] {local_task_job_runner.py:123} INFO - ::group::Pre task execution logs
[2024-12-24T05:23:22.949+0000] {taskinstance.py:2613} INFO - Dependencies all met for dep_context=non-requeueable deps ti=<TaskInstance: dag_Calendar_NTBK.NB_Notebook_job manual__2024-12-24T05:23:20.965203+00:00 [queued]>
[2024-12-24T05:23:22.960+0000] {taskinstance.py:2613} INFO - Dependencies all met for dep_context=requeueable deps ti=<TaskInstance: dag_Calendar_NTBK.NB_Notebook_job manual__2024-12-24T05:23:20.965203+00:00 [queued]>
[2024-12-24T05:23:22.960+0000] {taskinstance.py:2866} INFO - Starting attempt 1 of 1
[2024-12-24T05:23:22.986+0000] {taskinstance.py:2889} INFO - Executing <Task(DockerOperator): NB_Notebook_job> on 2024-12-24 05:23:20.965203+00:00
[2024-12-24T05:23:23.001+0000] {standard_task_runner.py:104} INFO - Running: ['***', 'tasks', 'run', 'dag_Calendar_NTBK', 'NB_Notebook_job', 'manual__2024-12-24T05:23:20.965203+00:00', '--job-id', '334', '--raw', '--subdir', 'DAGS_FOLDER/dag_calendar.py', '--cfg-path', '/tmp/tmpcdovh1x1']
[2024-12-24T05:23:23.013+0000] {standard_task_runner.py:105} INFO - Job 334: Subtask NB_Notebook_job
[2024-12-24T05:23:23.014+0000] {warnings.py:112} WARNING - /home/***/.local/lib/python3.12/site-packages/***/task/task_runner/standard_task_runner.py:70: DeprecationWarning: This process (pid=142) is multi-threaded, use of fork() may lead to deadlocks in the child.
  pid = os.fork()

[2024-12-24T05:23:23.017+0000] {standard_task_runner.py:72} INFO - Started process 145 to run task
[2024-12-24T05:23:23.087+0000] {task_command.py:467} INFO - Running <TaskInstance: dag_Calendar_NTBK.NB_Notebook_job manual__2024-12-24T05:23:20.965203+00:00 [running]> on host 1673b9432498
[2024-12-24T05:23:23.144+0000] {taskinstance.py:3132} INFO - Exporting env vars: AIRFLOW_CTX_DAG_OWNER='***' AIRFLOW_CTX_DAG_ID='dag_Calendar_NTBK' AIRFLOW_CTX_TASK_ID='NB_Notebook_job' AIRFLOW_CTX_EXECUTION_DATE='2024-12-24T05:23:20.965203+00:00' AIRFLOW_CTX_TRY_NUMBER='1' AIRFLOW_CTX_DAG_RUN_ID='manual__2024-12-24T05:23:20.965203+00:00'
[2024-12-24T05:23:23.145+0000] {taskinstance.py:731} INFO - ::endgroup::
[2024-12-24T05:23:23.642+0000] {docker.py:379} INFO - Starting docker container from image spark-cluster:version-1.0.0
[2024-12-24T05:23:25.441+0000] {docker.py:73} INFO - Input Notebook:  /Users/anoopm/my_jupyter_project/Scripts/NB_Calendar.ipynb
[2024-12-24T05:23:25.443+0000] {docker.py:73} INFO - Output Notebook: /Users/anoopm/my_jupyter_project/Scripts/output/NB_Calendar.ipynb
[2024-12-24T05:23:25.444+0000] {docker.py:73} INFO - Traceback (most recent call last):
[2024-12-24T05:23:25.444+0000] {docker.py:73} INFO -   File "/opt/conda/lib/python3.11/site-packages/papermill/iorw.py", line 199, in read
[2024-12-24T05:23:25.445+0000] {docker.py:73} INFO -     json.loads(path)
[2024-12-24T05:23:25.445+0000] {docker.py:73} INFO -   File "/opt/conda/lib/python3.11/json/__init__.py", line 346, in loads
[2024-12-24T05:23:25.446+0000] {docker.py:73} INFO -     return _default_decoder.decode(s)
[2024-12-24T05:23:25.446+0000] {docker.py:73} INFO -            ^^^^^^^^^^^^^^^^^^^^^^^^^^
[2024-12-24T05:23:25.446+0000] {docker.py:73} INFO -   File "/opt/conda/lib/python3.11/json/decoder.py", line 337, in decode
[2024-12-24T05:23:25.447+0000] {docker.py:73} INFO -     obj, end = self.raw_decode(s, idx=_w(s, 0).end())
[2024-12-24T05:23:25.447+0000] {docker.py:73} INFO -                ^^^^^^^^^^^^^^^^^^^^^^^^^^^^^^^^^^^^^^
[2024-12-24T05:23:25.448+0000] {docker.py:73} INFO -   File "/opt/conda/lib/python3.11/json/decoder.py", line 355, in raw_decode
[2024-12-24T05:23:25.448+0000] {docker.py:73} INFO -     raise JSONDecodeError("Expecting value", s, err.value) from None
[2024-12-24T05:23:25.449+0000] {docker.py:73} INFO - json.decoder.JSONDecodeError: Expecting value: line 1 column 1 (char 0)
[2024-12-24T05:23:25.451+0000] {docker.py:73} INFO - 
[2024-12-24T05:23:25.451+0000] {docker.py:73} INFO - During handling of the above exception, another exception occurred:
[2024-12-24T05:23:25.452+0000] {docker.py:73} INFO - 
[2024-12-24T05:23:25.452+0000] {docker.py:73} INFO - Traceback (most recent call last):
[2024-12-24T05:23:25.454+0000] {docker.py:73} INFO -   File "/opt/conda/bin/papermill", line 8, in <module>
[2024-12-24T05:23:25.456+0000] {docker.py:73} INFO -     sys.exit(papermill())
[2024-12-24T05:23:25.456+0000] {docker.py:73} INFO -              ^^^^^^^^^^^
[2024-12-24T05:23:25.457+0000] {docker.py:73} INFO -   File "/opt/conda/lib/python3.11/site-packages/click/core.py", line 1157, in __call__
[2024-12-24T05:23:25.457+0000] {docker.py:73} INFO -     return self.main(*args, **kwargs)
[2024-12-24T05:23:25.458+0000] {docker.py:73} INFO -            ^^^^^^^^^^^^^^^^^^^^^^^^^^
[2024-12-24T05:23:25.458+0000] {docker.py:73} INFO -   File "/opt/conda/lib/python3.11/site-packages/click/core.py", line 1078, in main
[2024-12-24T05:23:25.458+0000] {docker.py:73} INFO -     rv = self.invoke(ctx)
[2024-12-24T05:23:25.458+0000] {docker.py:73} INFO -          ^^^^^^^^^^^^^^^^
[2024-12-24T05:23:25.459+0000] {docker.py:73} INFO -   File "/opt/conda/lib/python3.11/site-packages/click/core.py", line 1434, in invoke
[2024-12-24T05:23:25.459+0000] {docker.py:73} INFO -     return ctx.invoke(self.callback, **ctx.params)
[2024-12-24T05:23:25.459+0000] {docker.py:73} INFO -            ^^^^^^^^^^^^^^^^^^^^^^^^^^^^^^^^^^^^^^^
[2024-12-24T05:23:25.460+0000] {docker.py:73} INFO -   File "/opt/conda/lib/python3.11/site-packages/click/core.py", line 783, in invoke
[2024-12-24T05:23:25.461+0000] {docker.py:73} INFO -     return __callback(*args, **kwargs)
[2024-12-24T05:23:25.462+0000] {docker.py:73} INFO -            ^^^^^^^^^^^^^^^^^^^^^^^^^^^
[2024-12-24T05:23:25.464+0000] {docker.py:73} INFO -   File "/opt/conda/lib/python3.11/site-packages/click/decorators.py", line 33, in new_func
[2024-12-24T05:23:25.464+0000] {docker.py:73} INFO -     return f(get_current_context(), *args, **kwargs)
[2024-12-24T05:23:25.465+0000] {docker.py:73} INFO -            ^^^^^^^^^^^^^^^^^^^^^^^^^^^^^^^^^^^^^^^^^
[2024-12-24T05:23:25.465+0000] {docker.py:73} INFO -   File "/opt/conda/lib/python3.11/site-packages/papermill/cli.py", line 235, in papermill
[2024-12-24T05:23:25.466+0000] {docker.py:73} INFO -     execute_notebook(
[2024-12-24T05:23:25.466+0000] {docker.py:73} INFO -   File "/opt/conda/lib/python3.11/site-packages/papermill/execute.py", line 89, in execute_notebook
[2024-12-24T05:23:25.467+0000] {docker.py:73} INFO -     nb = load_notebook_node(input_path)
[2024-12-24T05:23:25.468+0000] {docker.py:73} INFO -          ^^^^^^^^^^^^^^^^^^^^^^^^^^^^^^
[2024-12-24T05:23:25.469+0000] {docker.py:73} INFO -   File "/opt/conda/lib/python3.11/site-packages/papermill/iorw.py", line 499, in load_notebook_node
[2024-12-24T05:23:25.469+0000] {docker.py:73} INFO -     nb = nbformat.reads(papermill_io.read(notebook_path), as_version=4)
[2024-12-24T05:23:25.470+0000] {docker.py:73} INFO -                         ^^^^^^^^^^^^^^^^^^^^^^^^^^^^^^^^
[2024-12-24T05:23:25.471+0000] {docker.py:73} INFO -   File "/opt/conda/lib/python3.11/site-packages/papermill/iorw.py", line 96, in read
[2024-12-24T05:23:25.471+0000] {docker.py:73} INFO -     notebook_metadata = self.get_handler(path, extensions).read(path)
[2024-12-24T05:23:25.471+0000] {docker.py:73} INFO -                         ^^^^^^^^^^^^^^^^^^^^^^^^^^^^^^^^^^^^^^^^^^^^^
[2024-12-24T05:23:25.472+0000] {docker.py:73} INFO -   File "/opt/conda/lib/python3.11/site-packages/papermill/iorw.py", line 203, in read
[2024-12-24T05:23:25.474+0000] {docker.py:73} INFO -     raise e
[2024-12-24T05:23:25.475+0000] {docker.py:73} INFO -   File "/opt/conda/lib/python3.11/site-packages/papermill/iorw.py", line 193, in read
[2024-12-24T05:23:25.476+0000] {docker.py:73} INFO -     with open(path, encoding="utf-8") as f:
[2024-12-24T05:23:25.477+0000] {docker.py:73} INFO -          ^^^^^^^^^^^^^^^^^^^^^^^^^^^^
[2024-12-24T05:23:25.478+0000] {docker.py:73} INFO - FileNotFoundError: [Errno 2] No such file or directory: '/Users/anoopm/my_jupyter_project/Scripts/NB_Calendar.ipynb'
[2024-12-24T05:23:25.694+0000] {taskinstance.py:3311} ERROR - Task failed with exception
Traceback (most recent call last):
  File "/home/airflow/.local/lib/python3.12/site-packages/airflow/models/taskinstance.py", line 767, in _execute_task
    result = _execute_callable(context=context, **execute_callable_kwargs)
             ^^^^^^^^^^^^^^^^^^^^^^^^^^^^^^^^^^^^^^^^^^^^^^^^^^^^^^^^^^^^^
  File "/home/airflow/.local/lib/python3.12/site-packages/airflow/models/taskinstance.py", line 733, in _execute_callable
    return ExecutionCallableRunner(
           ^^^^^^^^^^^^^^^^^^^^^^^^
  File "/home/airflow/.local/lib/python3.12/site-packages/airflow/utils/operator_helpers.py", line 252, in run
    return self.func(*args, **kwargs)
           ^^^^^^^^^^^^^^^^^^^^^^^^^^
  File "/home/airflow/.local/lib/python3.12/site-packages/airflow/models/baseoperator.py", line 422, in wrapper
    return func(self, *args, **kwargs)
           ^^^^^^^^^^^^^^^^^^^^^^^^^^^
  File "/home/airflow/.local/lib/python3.12/site-packages/airflow/providers/docker/operators/docker.py", line 519, in execute
    return self._run_image()
           ^^^^^^^^^^^^^^^^^
  File "/home/airflow/.local/lib/python3.12/site-packages/airflow/providers/docker/operators/docker.py", line 396, in _run_image
    return self._run_image_with_mounts(self.mounts, add_tmp_variable=False)
           ^^^^^^^^^^^^^^^^^^^^^^^^^^^^^^^^^^^^^^^^^^^^^^^^^^^^^^^^^^^^^^^^
  File "/home/airflow/.local/lib/python3.12/site-packages/airflow/providers/docker/operators/docker.py", line 453, in _run_image_with_mounts
    raise DockerContainerFailedException(f"Docker container failed: {result!r}", logs=log_lines)
airflow.providers.docker.exceptions.DockerContainerFailedException: Docker container failed: {'StatusCode': 1}
[2024-12-24T05:23:25.733+0000] {taskinstance.py:1225} INFO - Marking task as FAILED. dag_id=dag_Calendar_NTBK, task_id=NB_Notebook_job, run_id=manual__2024-12-24T05:23:20.965203+00:00, execution_date=20241224T052320, start_date=20241224T052322, end_date=20241224T052325
[2024-12-24T05:23:25.805+0000] {taskinstance.py:340} INFO - ::group::Post task execution logs
[2024-12-24T05:23:25.807+0000] {standard_task_runner.py:124} ERROR - Failed to execute job 334 for task NB_Notebook_job (Docker container failed: {'StatusCode': 1}; 145)
Traceback (most recent call last):
  File "/home/airflow/.local/lib/python3.12/site-packages/airflow/task/task_runner/standard_task_runner.py", line 117, in _start_by_fork
    ret = args.func(args, dag=self.dag)
          ^^^^^^^^^^^^^^^^^^^^^^^^^^^^^
  File "/home/airflow/.local/lib/python3.12/site-packages/airflow/cli/cli_config.py", line 49, in command
    return func(*args, **kwargs)
           ^^^^^^^^^^^^^^^^^^^^^
  File "/home/airflow/.local/lib/python3.12/site-packages/airflow/utils/cli.py", line 116, in wrapper
    return f(*args, **kwargs)
           ^^^^^^^^^^^^^^^^^^
  File "/home/airflow/.local/lib/python3.12/site-packages/airflow/cli/commands/task_command.py", line 483, in task_run
    task_return_code = _run_task_by_selected_method(args, _dag, ti)
                       ^^^^^^^^^^^^^^^^^^^^^^^^^^^^^^^^^^^^^^^^^^^^
  File "/home/airflow/.local/lib/python3.12/site-packages/airflow/cli/commands/task_command.py", line 256, in _run_task_by_selected_method
    return _run_raw_task(args, ti)
           ^^^^^^^^^^^^^^^^^^^^^^^
  File "/home/airflow/.local/lib/python3.12/site-packages/airflow/cli/commands/task_command.py", line 341, in _run_raw_task
    return ti._run_raw_task(
           ^^^^^^^^^^^^^^^^^
  File "/home/airflow/.local/lib/python3.12/site-packages/airflow/utils/session.py", line 97, in wrapper
    return func(*args, session=session, **kwargs)
           ^^^^^^^^^^^^^^^^^^^^^^^^^^^^^^^^^^^^^^
  File "/home/airflow/.local/lib/python3.12/site-packages/airflow/models/taskinstance.py", line 3005, in _run_raw_task
    return _run_raw_task(
           ^^^^^^^^^^^^^^
  File "/home/airflow/.local/lib/python3.12/site-packages/airflow/models/taskinstance.py", line 273, in _run_raw_task
    TaskInstance._execute_task_with_callbacks(
  File "/home/airflow/.local/lib/python3.12/site-packages/airflow/models/taskinstance.py", line 3159, in _execute_task_with_callbacks
    result = self._execute_task(context, task_orig)
             ^^^^^^^^^^^^^^^^^^^^^^^^^^^^^^^^^^^^^^
  File "/home/airflow/.local/lib/python3.12/site-packages/airflow/models/taskinstance.py", line 3183, in _execute_task
    return _execute_task(self, context, task_orig)
           ^^^^^^^^^^^^^^^^^^^^^^^^^^^^^^^^^^^^^^^
  File "/home/airflow/.local/lib/python3.12/site-packages/airflow/models/taskinstance.py", line 767, in _execute_task
    result = _execute_callable(context=context, **execute_callable_kwargs)
             ^^^^^^^^^^^^^^^^^^^^^^^^^^^^^^^^^^^^^^^^^^^^^^^^^^^^^^^^^^^^^
  File "/home/airflow/.local/lib/python3.12/site-packages/airflow/models/taskinstance.py", line 733, in _execute_callable
    return ExecutionCallableRunner(
           ^^^^^^^^^^^^^^^^^^^^^^^^
  File "/home/airflow/.local/lib/python3.12/site-packages/airflow/utils/operator_helpers.py", line 252, in run
    return self.func(*args, **kwargs)
           ^^^^^^^^^^^^^^^^^^^^^^^^^^
  File "/home/airflow/.local/lib/python3.12/site-packages/airflow/models/baseoperator.py", line 422, in wrapper
    return func(self, *args, **kwargs)
           ^^^^^^^^^^^^^^^^^^^^^^^^^^^
  File "/home/airflow/.local/lib/python3.12/site-packages/airflow/providers/docker/operators/docker.py", line 519, in execute
    return self._run_image()
           ^^^^^^^^^^^^^^^^^
  File "/home/airflow/.local/lib/python3.12/site-packages/airflow/providers/docker/operators/docker.py", line 396, in _run_image
    return self._run_image_with_mounts(self.mounts, add_tmp_variable=False)
           ^^^^^^^^^^^^^^^^^^^^^^^^^^^^^^^^^^^^^^^^^^^^^^^^^^^^^^^^^^^^^^^^
  File "/home/airflow/.local/lib/python3.12/site-packages/airflow/providers/docker/operators/docker.py", line 453, in _run_image_with_mounts
    raise DockerContainerFailedException(f"Docker container failed: {result!r}", logs=log_lines)
airflow.providers.docker.exceptions.DockerContainerFailedException: Docker container failed: {'StatusCode': 1}
[2024-12-24T05:23:25.856+0000] {local_task_job_runner.py:266} INFO - Task exited with return code 1
[2024-12-24T05:23:25.907+0000] {taskinstance.py:3895} INFO - 1 downstream tasks scheduled from follow-on schedule check
[2024-12-24T05:23:25.910+0000] {local_task_job_runner.py:245} INFO - ::endgroup::
