[2024-12-20T18:35:11.388+0000] {local_task_job_runner.py:123} INFO - ::group::Pre task execution logs
[2024-12-20T18:35:11.420+0000] {taskinstance.py:2613} INFO - Dependencies all met for dep_context=non-requeueable deps ti=<TaskInstance: docker_dag.t2 manual__2024-12-20T18:34:59.730155+00:00 [queued]>
[2024-12-20T18:35:11.443+0000] {taskinstance.py:2613} INFO - Dependencies all met for dep_context=requeueable deps ti=<TaskInstance: docker_dag.t2 manual__2024-12-20T18:34:59.730155+00:00 [queued]>
[2024-12-20T18:35:11.448+0000] {taskinstance.py:2866} INFO - Starting attempt 1 of 1
[2024-12-20T18:35:11.473+0000] {taskinstance.py:2889} INFO - Executing <Task(DockerOperator): t2> on 2024-12-20 18:34:59.730155+00:00
[2024-12-20T18:35:11.509+0000] {warnings.py:112} WARNING - /home/***/.local/lib/python3.12/site-packages/***/task/task_runner/standard_task_runner.py:70: DeprecationWarning: This process (pid=65) is multi-threaded, use of fork() may lead to deadlocks in the child.
  pid = os.fork()

[2024-12-20T18:35:11.515+0000] {standard_task_runner.py:72} INFO - Started process 66 to run task
[2024-12-20T18:35:11.518+0000] {standard_task_runner.py:104} INFO - Running: ['***', 'tasks', 'run', 'docker_dag', 't2', 'manual__2024-12-20T18:34:59.730155+00:00', '--job-id', '80', '--raw', '--subdir', 'DAGS_FOLDER/A_dag_test.py', '--cfg-path', '/tmp/tmpvvywln9y']
[2024-12-20T18:35:11.520+0000] {standard_task_runner.py:105} INFO - Job 80: Subtask t2
[2024-12-20T18:35:11.829+0000] {task_command.py:467} INFO - Running <TaskInstance: docker_dag.t2 manual__2024-12-20T18:34:59.730155+00:00 [running]> on host 6cb319c12099
[2024-12-20T18:35:12.261+0000] {taskinstance.py:3132} INFO - Exporting env vars: AIRFLOW_CTX_DAG_OWNER='***' AIRFLOW_CTX_DAG_ID='docker_dag' AIRFLOW_CTX_TASK_ID='t2' AIRFLOW_CTX_EXECUTION_DATE='2024-12-20T18:34:59.730155+00:00' AIRFLOW_CTX_TRY_NUMBER='1' AIRFLOW_CTX_DAG_RUN_ID='manual__2024-12-20T18:34:59.730155+00:00'
[2024-12-20T18:35:12.279+0000] {logging_mixin.py:190} INFO - Task instance is in running state
[2024-12-20T18:35:12.281+0000] {logging_mixin.py:190} INFO -  Previous state of the Task instance: queued
[2024-12-20T18:35:12.281+0000] {logging_mixin.py:190} INFO - Current task name:t2 state:running start_date:2024-12-20 18:35:11.420489+00:00
[2024-12-20T18:35:12.282+0000] {logging_mixin.py:190} INFO - Dag name:docker_dag and current dag run status:running
[2024-12-20T18:35:12.282+0000] {taskinstance.py:731} INFO - ::endgroup::
[2024-12-20T18:35:12.696+0000] {docker.py:379} INFO - Starting docker container from image spark-cluster:version-1.0.0
[2024-12-20T18:35:12.771+0000] {docker.py:387} WARNING - Using remote engine or docker-in-docker and mounting temporary volume from host is not supported. Falling back to `mount_tmp_dir=False` mode. You can set `mount_tmp_dir` parameter to False to disable mounting and remove the warning
[2024-12-20T18:35:16.993+0000] {docker.py:73} INFO - Input Notebook:  /home/jovyan/Notebooks/NB_Calendar.ipynb
[2024-12-20T18:35:17.004+0000] {docker.py:73} INFO - Output Notebook: /home/jovyan/Notebooks/output/NB_Calendar.ipynb
[2024-12-20T18:35:17.415+0000] {docker.py:73} INFO - Executing:   0%|          | 0/14 [00:00<?, ?cell/s]
[2024-12-20T18:35:21.401+0000] {docker.py:73} INFO - Executing notebook with kernel: python3
[2024-12-20T18:35:22.972+0000] {docker.py:73} INFO - Executing:   7%|▋         | 1/14 [00:05<01:12,  5.55s/cell]
[2024-12-20T18:35:25.843+0000] {docker.py:73} INFO - :: loading settings :: url = jar:file:/usr/local/spark/jars/ivy-2.5.1.jar!/org/apache/ivy/core/settings/ivysettings.xml
[2024-12-20T18:35:25.946+0000] {docker.py:73} INFO - Ivy Default Cache set to: /home/jovyan/.ivy2/cache
[2024-12-20T18:35:25.947+0000] {docker.py:73} INFO - The jars for the packages stored in: /home/jovyan/.ivy2/jars
[2024-12-20T18:35:25.950+0000] {docker.py:73} INFO - io.delta#delta-spark_2.12 added as a dependency
[2024-12-20T18:35:25.951+0000] {docker.py:73} INFO - :: resolving dependencies :: org.apache.spark#spark-submit-parent-88e5a326-4455-4cc7-af83-34afbbefa83a;1.0
[2024-12-20T18:35:25.951+0000] {docker.py:73} INFO - 	confs: [default]
[2024-12-20T18:35:27.692+0000] {docker.py:73} INFO - 	found io.delta#delta-spark_2.12;3.2.0 in central
[2024-12-20T18:35:28.247+0000] {docker.py:73} INFO - 	found io.delta#delta-storage;3.2.0 in central
[2024-12-20T18:35:32.063+0000] {docker.py:73} INFO - 	found org.antlr#antlr4-runtime;4.9.3 in central
[2024-12-20T18:35:32.367+0000] {docker.py:73} INFO - downloading https://repo1.maven.org/maven2/io/delta/delta-spark_2.12/3.2.0/delta-spark_2.12-3.2.0.jar ...
[2024-12-20T18:35:41.869+0000] {docker.py:73} INFO - 	[SUCCESSFUL ] io.delta#delta-spark_2.12;3.2.0!delta-spark_2.12.jar (9786ms)
[2024-12-20T18:35:42.122+0000] {docker.py:73} INFO - downloading https://repo1.maven.org/maven2/io/delta/delta-storage/3.2.0/delta-storage-3.2.0.jar ...
[2024-12-20T18:35:42.391+0000] {docker.py:73} INFO - 	[SUCCESSFUL ] io.delta#delta-storage;3.2.0!delta-storage.jar (511ms)
[2024-12-20T18:35:42.650+0000] {docker.py:73} INFO - downloading https://repo1.maven.org/maven2/org/antlr/antlr4-runtime/4.9.3/antlr4-runtime-4.9.3.jar ...
[2024-12-20T18:35:43.042+0000] {docker.py:73} INFO - 	[SUCCESSFUL ] org.antlr#antlr4-runtime;4.9.3!antlr4-runtime.jar (639ms)
[2024-12-20T18:35:43.051+0000] {docker.py:73} INFO - :: resolution report :: resolve 6125ms :: artifacts dl 10963ms
[2024-12-20T18:35:43.053+0000] {docker.py:73} INFO - 	:: modules in use:
[2024-12-20T18:35:43.055+0000] {docker.py:73} INFO - 	io.delta#delta-spark_2.12;3.2.0 from central in [default]
[2024-12-20T18:35:43.055+0000] {docker.py:73} INFO - 	io.delta#delta-storage;3.2.0 from central in [default]
[2024-12-20T18:35:43.056+0000] {docker.py:73} INFO - 	org.antlr#antlr4-runtime;4.9.3 from central in [default]
[2024-12-20T18:35:43.056+0000] {docker.py:73} INFO - 	---------------------------------------------------------------------
[2024-12-20T18:35:43.057+0000] {docker.py:73} INFO - 	|                  |            modules            ||   artifacts   |
[2024-12-20T18:35:43.057+0000] {docker.py:73} INFO - 	|       conf       | number| search|dwnlded|evicted|| number|dwnlded|
[2024-12-20T18:35:43.057+0000] {docker.py:73} INFO - 	---------------------------------------------------------------------
[2024-12-20T18:35:43.057+0000] {docker.py:73} INFO - 	|      default     |   3   |   3   |   3   |   0   ||   3   |   3   |
[2024-12-20T18:35:43.058+0000] {docker.py:73} INFO - 	---------------------------------------------------------------------
[2024-12-20T18:35:43.078+0000] {docker.py:73} INFO - :: retrieving :: org.apache.spark#spark-submit-parent-88e5a326-4455-4cc7-af83-34afbbefa83a
[2024-12-20T18:35:43.081+0000] {docker.py:73} INFO - 	confs: [default]
[2024-12-20T18:35:43.125+0000] {docker.py:73} INFO - 	3 artifacts copied, 0 already retrieved (6321kB/50ms)
[2024-12-20T18:35:43.343+0000] {docker.py:73} INFO - 24/12/20 18:35:43 WARN NativeCodeLoader: Unable to load native-hadoop library for your platform... using builtin-java classes where applicable
[2024-12-20T18:35:43.531+0000] {docker.py:73} INFO - Setting default log level to "WARN".
[2024-12-20T18:35:43.532+0000] {docker.py:73} INFO - To adjust logging level use sc.setLogLevel(newLevel). For SparkR, use setLogLevel(newLevel).
[2024-12-20T18:35:44.443+0000] {docker.py:73} INFO - 24/12/20 18:35:44 WARN StandaloneSchedulerBackend: Dynamic allocation enabled without spark.executor.cores explicitly set, you may get more executors allocated than expected. It's recommended to set spark.executor.cores explicitly. Please check SPARK-30299 for more details.
[2024-12-20T18:35:45.101+0000] {docker.py:73} INFO - 24/12/20 18:35:45 WARN Utils: spark.executor.instances less than spark.dynamicAllocation.minExecutors is invalid, ignoring its setting, please update your configs.
[2024-12-20T18:35:49.023+0000] {docker.py:73} INFO - Executing:  21%|██▏       | 3/14 [00:31<02:01, 11.09s/cell]
[2024-12-20T18:35:58.679+0000] {docker.py:73} INFO - Executing:  43%|████▎     | 6/14 [00:41<00:50,  6.26s/cell]
[2024-12-20T18:35:59.004+0000] {docker.py:73} INFO - Executing:  50%|█████     | 7/14 [00:41<00:34,  4.92s/cell]
[2024-12-20T18:36:00.716+0000] {docker.py:73} INFO - Executing:  57%|█████▋    | 8/14 [00:43<00:24,  4.13s/cell]
[2024-12-20T18:36:04.095+0000] {docker.py:73} INFO - [Stage 0:>                                                          (0 + 2) / 2]
[2024-12-20T18:36:05.944+0000] {docker.py:73} INFO - 24/12/20 18:36:05 WARN TaskSetManager: Lost task 1.0 in stage 0.0 (TID 1) (172.19.0.5 executor 0): org.apache.spark.api.python.PythonException: Traceback (most recent call last):
[2024-12-20T18:36:05.953+0000] {docker.py:73} INFO -   File "/usr/local/spark/python/lib/pyspark.zip/pyspark/worker.py", line 1100, in main
[2024-12-20T18:36:05.955+0000] {docker.py:73} INFO -     raise PySparkRuntimeError(
[2024-12-20T18:36:05.955+0000] {docker.py:73} INFO - pyspark.errors.exceptions.base.PySparkRuntimeError: [PYTHON_VERSION_MISMATCH] Python in worker has different version (3, 12) than that in driver 3.11, PySpark cannot run with different minor versions.
[2024-12-20T18:36:05.956+0000] {docker.py:73} INFO - Please check environment variables PYSPARK_PYTHON and PYSPARK_DRIVER_PYTHON are correctly set.
[2024-12-20T18:36:05.956+0000] {docker.py:73} INFO - 
[2024-12-20T18:36:05.956+0000] {docker.py:73} INFO - 	at org.apache.spark.api.python.BasePythonRunner$ReaderIterator.handlePythonException(PythonRunner.scala:572)
[2024-12-20T18:36:05.957+0000] {docker.py:73} INFO - 	at org.apache.spark.api.python.PythonRunner$$anon$3.read(PythonRunner.scala:784)
[2024-12-20T18:36:05.961+0000] {docker.py:73} INFO - 	at org.apache.spark.api.python.PythonRunner$$anon$3.read(PythonRunner.scala:766)
[2024-12-20T18:36:05.961+0000] {docker.py:73} INFO - 	at org.apache.spark.api.python.BasePythonRunner$ReaderIterator.hasNext(PythonRunner.scala:525)
[2024-12-20T18:36:05.961+0000] {docker.py:73} INFO - 	at org.apache.spark.InterruptibleIterator.hasNext(InterruptibleIterator.scala:37)
[2024-12-20T18:36:05.961+0000] {docker.py:73} INFO - 	at scala.collection.Iterator$$anon$11.hasNext(Iterator.scala:491)
[2024-12-20T18:36:05.962+0000] {docker.py:73} INFO - 	at scala.collection.Iterator$$anon$10.hasNext(Iterator.scala:460)
[2024-12-20T18:36:05.962+0000] {docker.py:73} INFO - 	at scala.collection.Iterator$$anon$10.hasNext(Iterator.scala:460)
[2024-12-20T18:36:05.962+0000] {docker.py:73} INFO - 	at org.apache.spark.sql.catalyst.expressions.GeneratedClass$GeneratedIteratorForCodegenStage1.hashAgg_doAggregateWithoutKey_0$(Unknown Source)
[2024-12-20T18:36:05.962+0000] {docker.py:73} INFO - 	at org.apache.spark.sql.catalyst.expressions.GeneratedClass$GeneratedIteratorForCodegenStage1.processNext(Unknown Source)
[2024-12-20T18:36:05.962+0000] {docker.py:73} INFO - 	at org.apache.spark.sql.execution.BufferedRowIterator.hasNext(BufferedRowIterator.java:43)
[2024-12-20T18:36:05.963+0000] {docker.py:73} INFO - 	at org.apache.spark.sql.execution.WholeStageCodegenEvaluatorFactory$WholeStageCodegenPartitionEvaluator$$anon$1.hasNext(WholeStageCodegenEvaluatorFactory.scala:43)
[2024-12-20T18:36:05.963+0000] {docker.py:73} INFO - 	at scala.collection.Iterator$$anon$10.hasNext(Iterator.scala:460)
[2024-12-20T18:36:05.963+0000] {docker.py:73} INFO - 	at org.apache.spark.shuffle.sort.BypassMergeSortShuffleWriter.write(BypassMergeSortShuffleWriter.java:140)
[2024-12-20T18:36:05.963+0000] {docker.py:73} INFO - 	at org.apache.spark.shuffle.ShuffleWriteProcessor.write(ShuffleWriteProcessor.scala:59)
[2024-12-20T18:36:05.964+0000] {docker.py:73} INFO - 	at org.apache.spark.scheduler.ShuffleMapTask.runTask(ShuffleMapTask.scala:104)
[2024-12-20T18:36:05.964+0000] {docker.py:73} INFO - 	at org.apache.spark.scheduler.ShuffleMapTask.runTask(ShuffleMapTask.scala:54)
[2024-12-20T18:36:05.964+0000] {docker.py:73} INFO - 	at org.apache.spark.TaskContext.runTaskWithListeners(TaskContext.scala:161)
[2024-12-20T18:36:05.964+0000] {docker.py:73} INFO - 	at org.apache.spark.scheduler.Task.run(Task.scala:141)
[2024-12-20T18:36:05.964+0000] {docker.py:73} INFO - 	at org.apache.spark.executor.Executor$TaskRunner.$anonfun$run$4(Executor.scala:620)
[2024-12-20T18:36:05.964+0000] {docker.py:73} INFO - 	at org.apache.spark.util.SparkErrorUtils.tryWithSafeFinally(SparkErrorUtils.scala:64)
[2024-12-20T18:36:05.965+0000] {docker.py:73} INFO - 	at org.apache.spark.util.SparkErrorUtils.tryWithSafeFinally$(SparkErrorUtils.scala:61)
[2024-12-20T18:36:05.965+0000] {docker.py:73} INFO - 	at org.apache.spark.util.Utils$.tryWithSafeFinally(Utils.scala:94)
[2024-12-20T18:36:05.967+0000] {docker.py:73} INFO - 	at org.apache.spark.executor.Executor$TaskRunner.run(Executor.scala:623)
[2024-12-20T18:36:05.967+0000] {docker.py:73} INFO - 	at java.base/java.util.concurrent.ThreadPoolExecutor.runWorker(ThreadPoolExecutor.java:1136)
[2024-12-20T18:36:05.967+0000] {docker.py:73} INFO - 	at java.base/java.util.concurrent.ThreadPoolExecutor$Worker.run(ThreadPoolExecutor.java:635)
[2024-12-20T18:36:05.967+0000] {docker.py:73} INFO - 	at java.base/java.lang.Thread.run(Thread.java:840)
[2024-12-20T18:36:06.105+0000] {docker.py:73} INFO - 24/12/20 18:36:06 ERROR TaskSetManager: Task 1 in stage 0.0 failed 4 times; aborting job
[2024-12-20T18:36:06.155+0000] {docker.py:73} INFO - 24/12/20 18:36:06 WARN TaskSetManager: Lost task 0.3 in stage 0.0 (TID 7) (172.19.0.5 executor 0): TaskKilled (Stage cancelled: Job aborted due to stage failure: Task 1 in stage 0.0 failed 4 times, most recent failure: Lost task 1.3 in stage 0.0 (TID 6) (172.19.0.5 executor 0): org.apache.spark.api.python.PythonException: Traceback (most recent call last):
[2024-12-20T18:36:06.156+0000] {docker.py:73} INFO -   File "/usr/local/spark/python/lib/pyspark.zip/pyspark/worker.py", line 1100, in main
[2024-12-20T18:36:06.157+0000] {docker.py:73} INFO -     raise PySparkRuntimeError(
[2024-12-20T18:36:06.157+0000] {docker.py:73} INFO - pyspark.errors.exceptions.base.PySparkRuntimeError: [PYTHON_VERSION_MISMATCH] Python in worker has different version (3, 12) than that in driver 3.11, PySpark cannot run with different minor versions.
[2024-12-20T18:36:06.157+0000] {docker.py:73} INFO - Please check environment variables PYSPARK_PYTHON and PYSPARK_DRIVER_PYTHON are correctly set.
[2024-12-20T18:36:06.157+0000] {docker.py:73} INFO - 
[2024-12-20T18:36:06.158+0000] {docker.py:73} INFO - 	at org.apache.spark.api.python.BasePythonRunner$ReaderIterator.handlePythonException(PythonRunner.scala:572)
[2024-12-20T18:36:06.158+0000] {docker.py:73} INFO - 	at org.apache.spark.api.python.PythonRunner$$anon$3.read(PythonRunner.scala:784)
[2024-12-20T18:36:06.158+0000] {docker.py:73} INFO - 	at org.apache.spark.api.python.PythonRunner$$anon$3.read(PythonRunner.scala:766)
[2024-12-20T18:36:06.158+0000] {docker.py:73} INFO - 	at org.apache.spark.api.python.BasePythonRunner$ReaderIterator.hasNext(PythonRunner.scala:525)
[2024-12-20T18:36:06.158+0000] {docker.py:73} INFO - 	at org.apache.spark.InterruptibleIterator.hasNext(InterruptibleIterator.scala:37)
[2024-12-20T18:36:06.158+0000] {docker.py:73} INFO - 	at scala.collection.Iterator$$anon$11.hasNext(Iterator.scala:491)
[2024-12-20T18:36:06.158+0000] {docker.py:73} INFO - 	at scala.collection.Iterator$$anon$10.hasNext(Iterator.scala:460)
[2024-12-20T18:36:06.159+0000] {docker.py:73} INFO - 	at scala.collection.Iterator$$anon$10.hasNext(Iterator.scala:460)
[2024-12-20T18:36:06.159+0000] {docker.py:73} INFO - 	at org.apache.spark.sql.catalyst.expressions.GeneratedClass$GeneratedIteratorForCodegenStage1.hashAgg_doAggregateWithoutKey_0$(Unknown Source)
[2024-12-20T18:36:06.159+0000] {docker.py:73} INFO - 	at org.apache.spark.sql.catalyst.expressions.GeneratedClass$GeneratedIteratorForCodegenStage1.processNext(Unknown Source)
[2024-12-20T18:36:06.159+0000] {docker.py:73} INFO - 	at org.apache.spark.sql.execution.BufferedRowIterator.hasNext(BufferedRowIterator.java:43)
[2024-12-20T18:36:06.159+0000] {docker.py:73} INFO - 	at org.apache.spark.sql.execution.WholeStageCodegenEvaluatorFactory$WholeStageCodegenPartitionEvaluator$$anon$1.hasNext(WholeStageCodegenEvaluatorFactory.scala:43)
[2024-12-20T18:36:06.159+0000] {docker.py:73} INFO - 	at scala.collection.Iterator$$anon$10.hasNext(Iterator.scala:460)
[2024-12-20T18:36:06.160+0000] {docker.py:73} INFO - 	at org.apache.spark.shuffle.sort.BypassMergeSortShuffleWriter.write(BypassMergeSortShuffleWriter.java:140)
[2024-12-20T18:36:06.160+0000] {docker.py:73} INFO - 	at org.apache.spark.shuffle.ShuffleWriteProcessor.write(ShuffleWriteProcessor.scala:59)
[2024-12-20T18:36:06.160+0000] {docker.py:73} INFO - 	at org.apache.spark.scheduler.ShuffleMapTask.runTask(ShuffleMapTask.scala:104)
[2024-12-20T18:36:06.160+0000] {docker.py:73} INFO - 	at org.apache.spark.scheduler.ShuffleMapTask.runTask(ShuffleMapTask.scala:54)
[2024-12-20T18:36:06.160+0000] {docker.py:73} INFO - 	at org.apache.spark.TaskContext.runTaskWithListeners(TaskContext.scala:161)
[2024-12-20T18:36:06.160+0000] {docker.py:73} INFO - 	at org.apache.spark.scheduler.Task.run(Task.scala:141)
[2024-12-20T18:36:06.161+0000] {docker.py:73} INFO - 	at org.apache.spark.executor.Executor$TaskRunner.$anonfun$run$4(Executor.scala:620)
[2024-12-20T18:36:06.161+0000] {docker.py:73} INFO - 	at org.apache.spark.util.SparkErrorUtils.tryWithSafeFinally(SparkErrorUtils.scala:64)
[2024-12-20T18:36:06.161+0000] {docker.py:73} INFO - 	at org.apache.spark.util.SparkErrorUtils.tryWithSafeFinally$(SparkErrorUtils.scala:61)
[2024-12-20T18:36:06.162+0000] {docker.py:73} INFO - 	at org.apache.spark.util.Utils$.tryWithSafeFinally(Utils.scala:94)
[2024-12-20T18:36:06.162+0000] {docker.py:73} INFO - 	at org.apache.spark.executor.Executor$TaskRunner.run(Executor.scala:623)
[2024-12-20T18:36:06.163+0000] {docker.py:73} INFO - 	at java.base/java.util.concurrent.ThreadPoolExecutor.runWorker(ThreadPoolExecutor.java:1136)
[2024-12-20T18:36:06.163+0000] {docker.py:73} INFO - 	at java.base/java.util.concurrent.ThreadPoolExecutor$Worker.run(ThreadPoolExecutor.java:635)
[2024-12-20T18:36:06.164+0000] {docker.py:73} INFO - 	at java.base/java.lang.Thread.run(Thread.java:840)
[2024-12-20T18:36:06.164+0000] {docker.py:73} INFO - 
[2024-12-20T18:36:06.165+0000] {docker.py:73} INFO - Driver stacktrace:)
[2024-12-20T18:36:06.909+0000] {docker.py:73} INFO - Executing:  64%|██████▍   | 9/14 [00:49<00:23,  4.67s/cell]
[2024-12-20T18:36:09.561+0000] {docker.py:73} INFO - Executing:  64%|██████▍   | 9/14 [00:52<00:28,  5.79s/cell]
[2024-12-20T18:36:09.577+0000] {docker.py:73} INFO - Traceback (most recent call last):
[2024-12-20T18:36:09.578+0000] {docker.py:73} INFO -   File "/opt/conda/bin/papermill", line 8, in <module>
[2024-12-20T18:36:09.579+0000] {docker.py:73} INFO -     sys.exit(papermill())
[2024-12-20T18:36:09.579+0000] {docker.py:73} INFO -              ^^^^^^^^^^^
[2024-12-20T18:36:09.580+0000] {docker.py:73} INFO -   File "/opt/conda/lib/python3.11/site-packages/click/core.py", line 1157, in __call__
[2024-12-20T18:36:09.580+0000] {docker.py:73} INFO -     return self.main(*args, **kwargs)
[2024-12-20T18:36:09.581+0000] {docker.py:73} INFO -            ^^^^^^^^^^^^^^^^^^^^^^^^^^
[2024-12-20T18:36:09.581+0000] {docker.py:73} INFO -   File "/opt/conda/lib/python3.11/site-packages/click/core.py", line 1078, in main
[2024-12-20T18:36:09.582+0000] {docker.py:73} INFO -     rv = self.invoke(ctx)
[2024-12-20T18:36:09.582+0000] {docker.py:73} INFO -          ^^^^^^^^^^^^^^^^
[2024-12-20T18:36:09.583+0000] {docker.py:73} INFO -   File "/opt/conda/lib/python3.11/site-packages/click/core.py", line 1434, in invoke
[2024-12-20T18:36:09.583+0000] {docker.py:73} INFO -     return ctx.invoke(self.callback, **ctx.params)
[2024-12-20T18:36:09.583+0000] {docker.py:73} INFO -            ^^^^^^^^^^^^^^^^^^^^^^^^^^^^^^^^^^^^^^^
[2024-12-20T18:36:09.583+0000] {docker.py:73} INFO -   File "/opt/conda/lib/python3.11/site-packages/click/core.py", line 783, in invoke
[2024-12-20T18:36:09.583+0000] {docker.py:73} INFO -     return __callback(*args, **kwargs)
[2024-12-20T18:36:09.583+0000] {docker.py:73} INFO -            ^^^^^^^^^^^^^^^^^^^^^^^^^^^
[2024-12-20T18:36:09.584+0000] {docker.py:73} INFO -   File "/opt/conda/lib/python3.11/site-packages/click/decorators.py", line 33, in new_func
[2024-12-20T18:36:09.584+0000] {docker.py:73} INFO -     return f(get_current_context(), *args, **kwargs)
[2024-12-20T18:36:09.584+0000] {docker.py:73} INFO -            ^^^^^^^^^^^^^^^^^^^^^^^^^^^^^^^^^^^^^^^^^
[2024-12-20T18:36:09.584+0000] {docker.py:73} INFO -   File "/opt/conda/lib/python3.11/site-packages/papermill/cli.py", line 235, in papermill
[2024-12-20T18:36:09.585+0000] {docker.py:73} INFO -     execute_notebook(
[2024-12-20T18:36:09.585+0000] {docker.py:73} INFO -   File "/opt/conda/lib/python3.11/site-packages/papermill/execute.py", line 131, in execute_notebook
[2024-12-20T18:36:09.585+0000] {docker.py:73} INFO -     raise_for_execution_errors(nb, output_path)
[2024-12-20T18:36:09.585+0000] {docker.py:73} INFO -   File "/opt/conda/lib/python3.11/site-packages/papermill/execute.py", line 251, in raise_for_execution_errors
[2024-12-20T18:36:09.586+0000] {docker.py:73} INFO -     raise error
[2024-12-20T18:36:09.587+0000] {docker.py:73} INFO - papermill.exceptions.PapermillExecutionError: 
[2024-12-20T18:36:09.587+0000] {docker.py:73} INFO - ---------------------------------------------------------------------------
[2024-12-20T18:36:09.588+0000] {docker.py:73} INFO - Exception encountered at "In [9]":
[2024-12-20T18:36:09.588+0000] {docker.py:73} INFO - ---------------------------------------------------------------------------
[2024-12-20T18:36:09.589+0000] {docker.py:73} INFO - Py4JJavaError                             Traceback (most recent call last)
[2024-12-20T18:36:09.589+0000] {docker.py:73} INFO - Cell In[9], line 1
[2024-12-20T18:36:09.590+0000] {docker.py:73} INFO - ----> 1 print(df_output.count())
[2024-12-20T18:36:09.590+0000] {docker.py:73} INFO - 
[2024-12-20T18:36:09.591+0000] {docker.py:73} INFO - File /opt/conda/lib/python3.11/site-packages/pyspark/sql/dataframe.py:1240, in DataFrame.count(self)
[2024-12-20T18:36:09.591+0000] {docker.py:73} INFO -    1217 def count(self) -> int:
[2024-12-20T18:36:09.591+0000] {docker.py:73} INFO -    1218     """Returns the number of rows in this :class:`DataFrame`.
[2024-12-20T18:36:09.591+0000] {docker.py:73} INFO -    1219 
[2024-12-20T18:36:09.592+0000] {docker.py:73} INFO -    1220     .. versionadded:: 1.3.0
[2024-12-20T18:36:09.592+0000] {docker.py:73} INFO -    (...)
[2024-12-20T18:36:09.592+0000] {docker.py:73} INFO -    1238     3
[2024-12-20T18:36:09.593+0000] {docker.py:73} INFO -    1239     """
[2024-12-20T18:36:09.593+0000] {docker.py:73} INFO - -> 1240     return int(self._jdf.count())
[2024-12-20T18:36:09.593+0000] {docker.py:73} INFO - 
[2024-12-20T18:36:09.594+0000] {docker.py:73} INFO - File /opt/conda/lib/python3.11/site-packages/py4j/java_gateway.py:1322, in JavaMember.__call__(self, *args)
[2024-12-20T18:36:09.594+0000] {docker.py:73} INFO -    1316 command = proto.CALL_COMMAND_NAME +\
[2024-12-20T18:36:09.594+0000] {docker.py:73} INFO -    1317     self.command_header +\
[2024-12-20T18:36:09.594+0000] {docker.py:73} INFO -    1318     args_command +\
[2024-12-20T18:36:09.594+0000] {docker.py:73} INFO -    1319     proto.END_COMMAND_PART
[2024-12-20T18:36:09.594+0000] {docker.py:73} INFO -    1321 answer = self.gateway_client.send_command(command)
[2024-12-20T18:36:09.595+0000] {docker.py:73} INFO - -> 1322 return_value = get_return_value(
[2024-12-20T18:36:09.595+0000] {docker.py:73} INFO -    1323     answer, self.gateway_client, self.target_id, self.name)
[2024-12-20T18:36:09.595+0000] {docker.py:73} INFO -    1325 for temp_arg in temp_args:
[2024-12-20T18:36:09.595+0000] {docker.py:73} INFO -    1326     if hasattr(temp_arg, "_detach"):
[2024-12-20T18:36:09.596+0000] {docker.py:73} INFO - 
[2024-12-20T18:36:09.596+0000] {docker.py:73} INFO - File /opt/conda/lib/python3.11/site-packages/pyspark/errors/exceptions/captured.py:179, in capture_sql_exception.<locals>.deco(*a, **kw)
[2024-12-20T18:36:09.596+0000] {docker.py:73} INFO -     177 def deco(*a: Any, **kw: Any) -> Any:
[2024-12-20T18:36:09.596+0000] {docker.py:73} INFO -     178     try:
[2024-12-20T18:36:09.597+0000] {docker.py:73} INFO - --> 179         return f(*a, **kw)
[2024-12-20T18:36:09.597+0000] {docker.py:73} INFO -     180     except Py4JJavaError as e:
[2024-12-20T18:36:09.597+0000] {docker.py:73} INFO -     181         converted = convert_exception(e.java_exception)
[2024-12-20T18:36:09.597+0000] {docker.py:73} INFO - 
[2024-12-20T18:36:09.597+0000] {docker.py:73} INFO - File /opt/conda/lib/python3.11/site-packages/py4j/protocol.py:326, in get_return_value(answer, gateway_client, target_id, name)
[2024-12-20T18:36:09.598+0000] {docker.py:73} INFO -     324 value = OUTPUT_CONVERTER[type](answer[2:], gateway_client)
[2024-12-20T18:36:09.598+0000] {docker.py:73} INFO -     325 if answer[1] == REFERENCE_TYPE:
[2024-12-20T18:36:09.598+0000] {docker.py:73} INFO - --> 326     raise Py4JJavaError(
[2024-12-20T18:36:09.598+0000] {docker.py:73} INFO -     327         "An error occurred while calling {0}{1}{2}.\n".
[2024-12-20T18:36:09.598+0000] {docker.py:73} INFO -     328         format(target_id, ".", name), value)
[2024-12-20T18:36:09.599+0000] {docker.py:73} INFO -     329 else:
[2024-12-20T18:36:09.599+0000] {docker.py:73} INFO -     330     raise Py4JError(
[2024-12-20T18:36:09.599+0000] {docker.py:73} INFO -     331         "An error occurred while calling {0}{1}{2}. Trace:\n{3}\n".
[2024-12-20T18:36:09.599+0000] {docker.py:73} INFO -     332         format(target_id, ".", name, value))
[2024-12-20T18:36:09.599+0000] {docker.py:73} INFO - 
[2024-12-20T18:36:09.600+0000] {docker.py:73} INFO - Py4JJavaError: An error occurred while calling o115.count.
[2024-12-20T18:36:09.600+0000] {docker.py:73} INFO - : org.apache.spark.SparkException: Job aborted due to stage failure: Task 1 in stage 0.0 failed 4 times, most recent failure: Lost task 1.3 in stage 0.0 (TID 6) (172.19.0.5 executor 0): org.apache.spark.api.python.PythonException: Traceback (most recent call last):
[2024-12-20T18:36:09.600+0000] {docker.py:73} INFO -   File "/usr/local/spark/python/lib/pyspark.zip/pyspark/worker.py", line 1100, in main
[2024-12-20T18:36:09.600+0000] {docker.py:73} INFO -     raise PySparkRuntimeError(
[2024-12-20T18:36:09.600+0000] {docker.py:73} INFO - pyspark.errors.exceptions.base.PySparkRuntimeError: [PYTHON_VERSION_MISMATCH] Python in worker has different version (3, 12) than that in driver 3.11, PySpark cannot run with different minor versions.
[2024-12-20T18:36:09.600+0000] {docker.py:73} INFO - Please check environment variables PYSPARK_PYTHON and PYSPARK_DRIVER_PYTHON are correctly set.
[2024-12-20T18:36:09.601+0000] {docker.py:73} INFO - 
[2024-12-20T18:36:09.601+0000] {docker.py:73} INFO - 	at org.apache.spark.api.python.BasePythonRunner$ReaderIterator.handlePythonException(PythonRunner.scala:572)
[2024-12-20T18:36:09.601+0000] {docker.py:73} INFO - 	at org.apache.spark.api.python.PythonRunner$$anon$3.read(PythonRunner.scala:784)
[2024-12-20T18:36:09.601+0000] {docker.py:73} INFO - 	at org.apache.spark.api.python.PythonRunner$$anon$3.read(PythonRunner.scala:766)
[2024-12-20T18:36:09.601+0000] {docker.py:73} INFO - 	at org.apache.spark.api.python.BasePythonRunner$ReaderIterator.hasNext(PythonRunner.scala:525)
[2024-12-20T18:36:09.602+0000] {docker.py:73} INFO - 	at org.apache.spark.InterruptibleIterator.hasNext(InterruptibleIterator.scala:37)
[2024-12-20T18:36:09.602+0000] {docker.py:73} INFO - 	at scala.collection.Iterator$$anon$11.hasNext(Iterator.scala:491)
[2024-12-20T18:36:09.602+0000] {docker.py:73} INFO - 	at scala.collection.Iterator$$anon$10.hasNext(Iterator.scala:460)
[2024-12-20T18:36:09.602+0000] {docker.py:73} INFO - 	at scala.collection.Iterator$$anon$10.hasNext(Iterator.scala:460)
[2024-12-20T18:36:09.603+0000] {docker.py:73} INFO - 	at org.apache.spark.sql.catalyst.expressions.GeneratedClass$GeneratedIteratorForCodegenStage1.hashAgg_doAggregateWithoutKey_0$(Unknown Source)
[2024-12-20T18:36:09.603+0000] {docker.py:73} INFO - 	at org.apache.spark.sql.catalyst.expressions.GeneratedClass$GeneratedIteratorForCodegenStage1.processNext(Unknown Source)
[2024-12-20T18:36:09.603+0000] {docker.py:73} INFO - 	at org.apache.spark.sql.execution.BufferedRowIterator.hasNext(BufferedRowIterator.java:43)
[2024-12-20T18:36:09.604+0000] {docker.py:73} INFO - 	at org.apache.spark.sql.execution.WholeStageCodegenEvaluatorFactory$WholeStageCodegenPartitionEvaluator$$anon$1.hasNext(WholeStageCodegenEvaluatorFactory.scala:43)
[2024-12-20T18:36:09.605+0000] {docker.py:73} INFO - 	at scala.collection.Iterator$$anon$10.hasNext(Iterator.scala:460)
[2024-12-20T18:36:09.605+0000] {docker.py:73} INFO - 	at org.apache.spark.shuffle.sort.BypassMergeSortShuffleWriter.write(BypassMergeSortShuffleWriter.java:140)
[2024-12-20T18:36:09.606+0000] {docker.py:73} INFO - 	at org.apache.spark.shuffle.ShuffleWriteProcessor.write(ShuffleWriteProcessor.scala:59)
[2024-12-20T18:36:09.606+0000] {docker.py:73} INFO - 	at org.apache.spark.scheduler.ShuffleMapTask.runTask(ShuffleMapTask.scala:104)
[2024-12-20T18:36:09.607+0000] {docker.py:73} INFO - 	at org.apache.spark.scheduler.ShuffleMapTask.runTask(ShuffleMapTask.scala:54)
[2024-12-20T18:36:09.607+0000] {docker.py:73} INFO - 	at org.apache.spark.TaskContext.runTaskWithListeners(TaskContext.scala:161)
[2024-12-20T18:36:09.607+0000] {docker.py:73} INFO - 	at org.apache.spark.scheduler.Task.run(Task.scala:141)
[2024-12-20T18:36:09.608+0000] {docker.py:73} INFO - 	at org.apache.spark.executor.Executor$TaskRunner.$anonfun$run$4(Executor.scala:620)
[2024-12-20T18:36:09.608+0000] {docker.py:73} INFO - 	at org.apache.spark.util.SparkErrorUtils.tryWithSafeFinally(SparkErrorUtils.scala:64)
[2024-12-20T18:36:09.608+0000] {docker.py:73} INFO - 	at org.apache.spark.util.SparkErrorUtils.tryWithSafeFinally$(SparkErrorUtils.scala:61)
[2024-12-20T18:36:09.608+0000] {docker.py:73} INFO - 	at org.apache.spark.util.Utils$.tryWithSafeFinally(Utils.scala:94)
[2024-12-20T18:36:09.609+0000] {docker.py:73} INFO - 	at org.apache.spark.executor.Executor$TaskRunner.run(Executor.scala:623)
[2024-12-20T18:36:09.609+0000] {docker.py:73} INFO - 	at java.base/java.util.concurrent.ThreadPoolExecutor.runWorker(ThreadPoolExecutor.java:1136)
[2024-12-20T18:36:09.609+0000] {docker.py:73} INFO - 	at java.base/java.util.concurrent.ThreadPoolExecutor$Worker.run(ThreadPoolExecutor.java:635)
[2024-12-20T18:36:09.609+0000] {docker.py:73} INFO - 	at java.base/java.lang.Thread.run(Thread.java:840)
[2024-12-20T18:36:09.610+0000] {docker.py:73} INFO - 
[2024-12-20T18:36:09.610+0000] {docker.py:73} INFO - Driver stacktrace:
[2024-12-20T18:36:09.610+0000] {docker.py:73} INFO - 	at org.apache.spark.scheduler.DAGScheduler.failJobAndIndependentStages(DAGScheduler.scala:2844)
[2024-12-20T18:36:09.610+0000] {docker.py:73} INFO - 	at org.apache.spark.scheduler.DAGScheduler.$anonfun$abortStage$2(DAGScheduler.scala:2780)
[2024-12-20T18:36:09.611+0000] {docker.py:73} INFO - 	at org.apache.spark.scheduler.DAGScheduler.$anonfun$abortStage$2$adapted(DAGScheduler.scala:2779)
[2024-12-20T18:36:09.611+0000] {docker.py:73} INFO - 	at scala.collection.mutable.ResizableArray.foreach(ResizableArray.scala:62)
[2024-12-20T18:36:09.611+0000] {docker.py:73} INFO - 	at scala.collection.mutable.ResizableArray.foreach$(ResizableArray.scala:55)
[2024-12-20T18:36:09.611+0000] {docker.py:73} INFO - 	at scala.collection.mutable.ArrayBuffer.foreach(ArrayBuffer.scala:49)
[2024-12-20T18:36:09.612+0000] {docker.py:73} INFO - 	at org.apache.spark.scheduler.DAGScheduler.abortStage(DAGScheduler.scala:2779)
[2024-12-20T18:36:09.612+0000] {docker.py:73} INFO - 	at org.apache.spark.scheduler.DAGScheduler.$anonfun$handleTaskSetFailed$1(DAGScheduler.scala:1242)
[2024-12-20T18:36:09.612+0000] {docker.py:73} INFO - 	at org.apache.spark.scheduler.DAGScheduler.$anonfun$handleTaskSetFailed$1$adapted(DAGScheduler.scala:1242)
[2024-12-20T18:36:09.612+0000] {docker.py:73} INFO - 	at scala.Option.foreach(Option.scala:407)
[2024-12-20T18:36:09.612+0000] {docker.py:73} INFO - 	at org.apache.spark.scheduler.DAGScheduler.handleTaskSetFailed(DAGScheduler.scala:1242)
[2024-12-20T18:36:09.612+0000] {docker.py:73} INFO - 	at org.apache.spark.scheduler.DAGSchedulerEventProcessLoop.doOnReceive(DAGScheduler.scala:3048)
[2024-12-20T18:36:09.613+0000] {docker.py:73} INFO - 	at org.apache.spark.scheduler.DAGSchedulerEventProcessLoop.onReceive(DAGScheduler.scala:2982)
[2024-12-20T18:36:09.613+0000] {docker.py:73} INFO - 	at org.apache.spark.scheduler.DAGSchedulerEventProcessLoop.onReceive(DAGScheduler.scala:2971)
[2024-12-20T18:36:09.613+0000] {docker.py:73} INFO - 	at org.apache.spark.util.EventLoop$$anon$1.run(EventLoop.scala:49)
[2024-12-20T18:36:09.614+0000] {docker.py:73} INFO - Caused by: org.apache.spark.api.python.PythonException: Traceback (most recent call last):
[2024-12-20T18:36:09.614+0000] {docker.py:73} INFO -   File "/usr/local/spark/python/lib/pyspark.zip/pyspark/worker.py", line 1100, in main
[2024-12-20T18:36:09.614+0000] {docker.py:73} INFO -     raise PySparkRuntimeError(
[2024-12-20T18:36:09.614+0000] {docker.py:73} INFO - pyspark.errors.exceptions.base.PySparkRuntimeError: [PYTHON_VERSION_MISMATCH] Python in worker has different version (3, 12) than that in driver 3.11, PySpark cannot run with different minor versions.
[2024-12-20T18:36:09.614+0000] {docker.py:73} INFO - Please check environment variables PYSPARK_PYTHON and PYSPARK_DRIVER_PYTHON are correctly set.
[2024-12-20T18:36:09.615+0000] {docker.py:73} INFO - 
[2024-12-20T18:36:09.615+0000] {docker.py:73} INFO - 	at org.apache.spark.api.python.BasePythonRunner$ReaderIterator.handlePythonException(PythonRunner.scala:572)
[2024-12-20T18:36:09.615+0000] {docker.py:73} INFO - 	at org.apache.spark.api.python.PythonRunner$$anon$3.read(PythonRunner.scala:784)
[2024-12-20T18:36:09.615+0000] {docker.py:73} INFO - 	at org.apache.spark.api.python.PythonRunner$$anon$3.read(PythonRunner.scala:766)
[2024-12-20T18:36:09.615+0000] {docker.py:73} INFO - 	at org.apache.spark.api.python.BasePythonRunner$ReaderIterator.hasNext(PythonRunner.scala:525)
[2024-12-20T18:36:09.616+0000] {docker.py:73} INFO - 	at org.apache.spark.InterruptibleIterator.hasNext(InterruptibleIterator.scala:37)
[2024-12-20T18:36:09.616+0000] {docker.py:73} INFO - 	at scala.collection.Iterator$$anon$11.hasNext(Iterator.scala:491)
[2024-12-20T18:36:09.617+0000] {docker.py:73} INFO - 	at scala.collection.Iterator$$anon$10.hasNext(Iterator.scala:460)
[2024-12-20T18:36:09.617+0000] {docker.py:73} INFO - 	at scala.collection.Iterator$$anon$10.hasNext(Iterator.scala:460)
[2024-12-20T18:36:09.617+0000] {docker.py:73} INFO - 	at org.apache.spark.sql.catalyst.expressions.GeneratedClass$GeneratedIteratorForCodegenStage1.hashAgg_doAggregateWithoutKey_0$(Unknown Source)
[2024-12-20T18:36:09.617+0000] {docker.py:73} INFO - 	at org.apache.spark.sql.catalyst.expressions.GeneratedClass$GeneratedIteratorForCodegenStage1.processNext(Unknown Source)
[2024-12-20T18:36:09.618+0000] {docker.py:73} INFO - 	at org.apache.spark.sql.execution.BufferedRowIterator.hasNext(BufferedRowIterator.java:43)
[2024-12-20T18:36:09.618+0000] {docker.py:73} INFO - 	at org.apache.spark.sql.execution.WholeStageCodegenEvaluatorFactory$WholeStageCodegenPartitionEvaluator$$anon$1.hasNext(WholeStageCodegenEvaluatorFactory.scala:43)
[2024-12-20T18:36:09.618+0000] {docker.py:73} INFO - 	at scala.collection.Iterator$$anon$10.hasNext(Iterator.scala:460)
[2024-12-20T18:36:09.619+0000] {docker.py:73} INFO - 	at org.apache.spark.shuffle.sort.BypassMergeSortShuffleWriter.write(BypassMergeSortShuffleWriter.java:140)
[2024-12-20T18:36:09.620+0000] {docker.py:73} INFO - 	at org.apache.spark.shuffle.ShuffleWriteProcessor.write(ShuffleWriteProcessor.scala:59)
[2024-12-20T18:36:09.620+0000] {docker.py:73} INFO - 	at org.apache.spark.scheduler.ShuffleMapTask.runTask(ShuffleMapTask.scala:104)
[2024-12-20T18:36:09.620+0000] {docker.py:73} INFO - 	at org.apache.spark.scheduler.ShuffleMapTask.runTask(ShuffleMapTask.scala:54)
[2024-12-20T18:36:09.621+0000] {docker.py:73} INFO - 	at org.apache.spark.TaskContext.runTaskWithListeners(TaskContext.scala:161)
[2024-12-20T18:36:09.622+0000] {docker.py:73} INFO - 	at org.apache.spark.scheduler.Task.run(Task.scala:141)
[2024-12-20T18:36:09.622+0000] {docker.py:73} INFO - 	at org.apache.spark.executor.Executor$TaskRunner.$anonfun$run$4(Executor.scala:620)
[2024-12-20T18:36:09.623+0000] {docker.py:73} INFO - 	at org.apache.spark.util.SparkErrorUtils.tryWithSafeFinally(SparkErrorUtils.scala:64)
[2024-12-20T18:36:09.623+0000] {docker.py:73} INFO - 	at org.apache.spark.util.SparkErrorUtils.tryWithSafeFinally$(SparkErrorUtils.scala:61)
[2024-12-20T18:36:09.623+0000] {docker.py:73} INFO - 	at org.apache.spark.util.Utils$.tryWithSafeFinally(Utils.scala:94)
[2024-12-20T18:36:09.624+0000] {docker.py:73} INFO - 	at org.apache.spark.executor.Executor$TaskRunner.run(Executor.scala:623)
[2024-12-20T18:36:09.624+0000] {docker.py:73} INFO - 	at java.base/java.util.concurrent.ThreadPoolExecutor.runWorker(ThreadPoolExecutor.java:1136)
[2024-12-20T18:36:09.624+0000] {docker.py:73} INFO - 	at java.base/java.util.concurrent.ThreadPoolExecutor$Worker.run(ThreadPoolExecutor.java:635)
[2024-12-20T18:36:09.624+0000] {docker.py:73} INFO - 	at java.base/java.lang.Thread.run(Thread.java:840)
[2024-12-20T18:36:10.190+0000] {taskinstance.py:3311} ERROR - Task failed with exception
Traceback (most recent call last):
  File "/home/airflow/.local/lib/python3.12/site-packages/docker/api/client.py", line 275, in _raise_for_status
    response.raise_for_status()
  File "/home/airflow/.local/lib/python3.12/site-packages/requests/models.py", line 1024, in raise_for_status
    raise HTTPError(http_error_msg, response=self)
requests.exceptions.HTTPError: 400 Client Error: Bad Request for url: http+docker://localhost/v1.47/containers/create

The above exception was the direct cause of the following exception:

Traceback (most recent call last):
  File "/home/airflow/.local/lib/python3.12/site-packages/airflow/providers/docker/operators/docker.py", line 384, in _run_image
    return self._run_image_with_mounts([*self.mounts, tmp_mount], add_tmp_variable=True)
           ^^^^^^^^^^^^^^^^^^^^^^^^^^^^^^^^^^^^^^^^^^^^^^^^^^^^^^^^^^^^^^^^^^^^^^^^^^^^^
  File "/home/airflow/.local/lib/python3.12/site-packages/airflow/providers/docker/operators/docker.py", line 411, in _run_image_with_mounts
    self.container = self.cli.create_container(
                     ^^^^^^^^^^^^^^^^^^^^^^^^^^
  File "/home/airflow/.local/lib/python3.12/site-packages/docker/api/container.py", line 440, in create_container
    return self.create_container_from_config(config, name, platform)
           ^^^^^^^^^^^^^^^^^^^^^^^^^^^^^^^^^^^^^^^^^^^^^^^^^^^^^^^^^
  File "/home/airflow/.local/lib/python3.12/site-packages/docker/api/container.py", line 457, in create_container_from_config
    return self._result(res, True)
           ^^^^^^^^^^^^^^^^^^^^^^^
  File "/home/airflow/.local/lib/python3.12/site-packages/docker/api/client.py", line 281, in _result
    self._raise_for_status(response)
  File "/home/airflow/.local/lib/python3.12/site-packages/docker/api/client.py", line 277, in _raise_for_status
    raise create_api_error_from_http_exception(e) from e
          ^^^^^^^^^^^^^^^^^^^^^^^^^^^^^^^^^^^^^^^
  File "/home/airflow/.local/lib/python3.12/site-packages/docker/errors.py", line 39, in create_api_error_from_http_exception
    raise cls(e, response=response, explanation=explanation) from e
docker.errors.APIError: 400 Client Error for http+docker://localhost/v1.47/containers/create: Bad Request ("invalid mount config for type "bind": bind source path does not exist: /host_mnt/private/tmp/airflowtmpqe_pkvwz")

During handling of the above exception, another exception occurred:

Traceback (most recent call last):
  File "/home/airflow/.local/lib/python3.12/site-packages/airflow/models/taskinstance.py", line 767, in _execute_task
    result = _execute_callable(context=context, **execute_callable_kwargs)
             ^^^^^^^^^^^^^^^^^^^^^^^^^^^^^^^^^^^^^^^^^^^^^^^^^^^^^^^^^^^^^
  File "/home/airflow/.local/lib/python3.12/site-packages/airflow/models/taskinstance.py", line 733, in _execute_callable
    return ExecutionCallableRunner(
           ^^^^^^^^^^^^^^^^^^^^^^^^
  File "/home/airflow/.local/lib/python3.12/site-packages/airflow/utils/operator_helpers.py", line 252, in run
    return self.func(*args, **kwargs)
           ^^^^^^^^^^^^^^^^^^^^^^^^^^
  File "/home/airflow/.local/lib/python3.12/site-packages/airflow/models/baseoperator.py", line 422, in wrapper
    return func(self, *args, **kwargs)
           ^^^^^^^^^^^^^^^^^^^^^^^^^^^
  File "/home/airflow/.local/lib/python3.12/site-packages/airflow/providers/docker/operators/docker.py", line 519, in execute
    return self._run_image()
           ^^^^^^^^^^^^^^^^^
  File "/home/airflow/.local/lib/python3.12/site-packages/airflow/providers/docker/operators/docker.py", line 393, in _run_image
    return self._run_image_with_mounts(self.mounts, add_tmp_variable=False)
           ^^^^^^^^^^^^^^^^^^^^^^^^^^^^^^^^^^^^^^^^^^^^^^^^^^^^^^^^^^^^^^^^
  File "/home/airflow/.local/lib/python3.12/site-packages/airflow/providers/docker/operators/docker.py", line 453, in _run_image_with_mounts
    raise DockerContainerFailedException(f"Docker container failed: {result!r}", logs=log_lines)
airflow.providers.docker.exceptions.DockerContainerFailedException: Docker container failed: {'StatusCode': 1}
[2024-12-20T18:36:10.261+0000] {logging_mixin.py:190} INFO - Task instance in failure state
[2024-12-20T18:36:10.262+0000] {logging_mixin.py:190} INFO - Task start:2024-12-20 18:35:11.420489+00:00 end:2024-12-20 18:36:10.238033+00:00 duration:58.817544
[2024-12-20T18:36:10.263+0000] {logging_mixin.py:190} INFO - Task:<Task(DockerOperator): t2> dag:<DAG: docker_dag> dagrun:<DagRun docker_dag @ 2024-12-20 18:34:59.730155+00:00: manual__2024-12-20T18:34:59.730155+00:00, state:running, queued_at: 2024-12-20 18:34:59.784201+00:00. externally triggered: True>
[2024-12-20T18:36:10.264+0000] {logging_mixin.py:190} INFO - Failure caused by Docker container failed: {'StatusCode': 1}
[2024-12-20T18:36:10.269+0000] {taskinstance.py:1225} INFO - Marking task as FAILED. dag_id=docker_dag, task_id=t2, run_id=manual__2024-12-20T18:34:59.730155+00:00, execution_date=20241220T183459, start_date=20241220T183511, end_date=20241220T183610
[2024-12-20T18:36:10.324+0000] {taskinstance.py:340} INFO - ::group::Post task execution logs
[2024-12-20T18:36:10.330+0000] {standard_task_runner.py:124} ERROR - Failed to execute job 80 for task t2 (Docker container failed: {'StatusCode': 1}; 66)
Traceback (most recent call last):
  File "/home/airflow/.local/lib/python3.12/site-packages/docker/api/client.py", line 275, in _raise_for_status
    response.raise_for_status()
  File "/home/airflow/.local/lib/python3.12/site-packages/requests/models.py", line 1024, in raise_for_status
    raise HTTPError(http_error_msg, response=self)
requests.exceptions.HTTPError: 400 Client Error: Bad Request for url: http+docker://localhost/v1.47/containers/create

The above exception was the direct cause of the following exception:

Traceback (most recent call last):
  File "/home/airflow/.local/lib/python3.12/site-packages/airflow/providers/docker/operators/docker.py", line 384, in _run_image
    return self._run_image_with_mounts([*self.mounts, tmp_mount], add_tmp_variable=True)
           ^^^^^^^^^^^^^^^^^^^^^^^^^^^^^^^^^^^^^^^^^^^^^^^^^^^^^^^^^^^^^^^^^^^^^^^^^^^^^
  File "/home/airflow/.local/lib/python3.12/site-packages/airflow/providers/docker/operators/docker.py", line 411, in _run_image_with_mounts
    self.container = self.cli.create_container(
                     ^^^^^^^^^^^^^^^^^^^^^^^^^^
  File "/home/airflow/.local/lib/python3.12/site-packages/docker/api/container.py", line 440, in create_container
    return self.create_container_from_config(config, name, platform)
           ^^^^^^^^^^^^^^^^^^^^^^^^^^^^^^^^^^^^^^^^^^^^^^^^^^^^^^^^^
  File "/home/airflow/.local/lib/python3.12/site-packages/docker/api/container.py", line 457, in create_container_from_config
    return self._result(res, True)
           ^^^^^^^^^^^^^^^^^^^^^^^
  File "/home/airflow/.local/lib/python3.12/site-packages/docker/api/client.py", line 281, in _result
    self._raise_for_status(response)
  File "/home/airflow/.local/lib/python3.12/site-packages/docker/api/client.py", line 277, in _raise_for_status
    raise create_api_error_from_http_exception(e) from e
          ^^^^^^^^^^^^^^^^^^^^^^^^^^^^^^^^^^^^^^^
  File "/home/airflow/.local/lib/python3.12/site-packages/docker/errors.py", line 39, in create_api_error_from_http_exception
    raise cls(e, response=response, explanation=explanation) from e
docker.errors.APIError: 400 Client Error for http+docker://localhost/v1.47/containers/create: Bad Request ("invalid mount config for type "bind": bind source path does not exist: /host_mnt/private/tmp/airflowtmpqe_pkvwz")

During handling of the above exception, another exception occurred:

Traceback (most recent call last):
  File "/home/airflow/.local/lib/python3.12/site-packages/airflow/task/task_runner/standard_task_runner.py", line 117, in _start_by_fork
    ret = args.func(args, dag=self.dag)
          ^^^^^^^^^^^^^^^^^^^^^^^^^^^^^
  File "/home/airflow/.local/lib/python3.12/site-packages/airflow/cli/cli_config.py", line 49, in command
    return func(*args, **kwargs)
           ^^^^^^^^^^^^^^^^^^^^^
  File "/home/airflow/.local/lib/python3.12/site-packages/airflow/utils/cli.py", line 116, in wrapper
    return f(*args, **kwargs)
           ^^^^^^^^^^^^^^^^^^
  File "/home/airflow/.local/lib/python3.12/site-packages/airflow/cli/commands/task_command.py", line 483, in task_run
    task_return_code = _run_task_by_selected_method(args, _dag, ti)
                       ^^^^^^^^^^^^^^^^^^^^^^^^^^^^^^^^^^^^^^^^^^^^
  File "/home/airflow/.local/lib/python3.12/site-packages/airflow/cli/commands/task_command.py", line 256, in _run_task_by_selected_method
    return _run_raw_task(args, ti)
           ^^^^^^^^^^^^^^^^^^^^^^^
  File "/home/airflow/.local/lib/python3.12/site-packages/airflow/cli/commands/task_command.py", line 341, in _run_raw_task
    return ti._run_raw_task(
           ^^^^^^^^^^^^^^^^^
  File "/home/airflow/.local/lib/python3.12/site-packages/airflow/utils/session.py", line 97, in wrapper
    return func(*args, session=session, **kwargs)
           ^^^^^^^^^^^^^^^^^^^^^^^^^^^^^^^^^^^^^^
  File "/home/airflow/.local/lib/python3.12/site-packages/airflow/models/taskinstance.py", line 3005, in _run_raw_task
    return _run_raw_task(
           ^^^^^^^^^^^^^^
  File "/home/airflow/.local/lib/python3.12/site-packages/airflow/models/taskinstance.py", line 273, in _run_raw_task
    TaskInstance._execute_task_with_callbacks(
  File "/home/airflow/.local/lib/python3.12/site-packages/airflow/models/taskinstance.py", line 3159, in _execute_task_with_callbacks
    result = self._execute_task(context, task_orig)
             ^^^^^^^^^^^^^^^^^^^^^^^^^^^^^^^^^^^^^^
  File "/home/airflow/.local/lib/python3.12/site-packages/airflow/models/taskinstance.py", line 3183, in _execute_task
    return _execute_task(self, context, task_orig)
           ^^^^^^^^^^^^^^^^^^^^^^^^^^^^^^^^^^^^^^^
  File "/home/airflow/.local/lib/python3.12/site-packages/airflow/models/taskinstance.py", line 767, in _execute_task
    result = _execute_callable(context=context, **execute_callable_kwargs)
             ^^^^^^^^^^^^^^^^^^^^^^^^^^^^^^^^^^^^^^^^^^^^^^^^^^^^^^^^^^^^^
  File "/home/airflow/.local/lib/python3.12/site-packages/airflow/models/taskinstance.py", line 733, in _execute_callable
    return ExecutionCallableRunner(
           ^^^^^^^^^^^^^^^^^^^^^^^^
  File "/home/airflow/.local/lib/python3.12/site-packages/airflow/utils/operator_helpers.py", line 252, in run
    return self.func(*args, **kwargs)
           ^^^^^^^^^^^^^^^^^^^^^^^^^^
  File "/home/airflow/.local/lib/python3.12/site-packages/airflow/models/baseoperator.py", line 422, in wrapper
    return func(self, *args, **kwargs)
           ^^^^^^^^^^^^^^^^^^^^^^^^^^^
  File "/home/airflow/.local/lib/python3.12/site-packages/airflow/providers/docker/operators/docker.py", line 519, in execute
    return self._run_image()
           ^^^^^^^^^^^^^^^^^
  File "/home/airflow/.local/lib/python3.12/site-packages/airflow/providers/docker/operators/docker.py", line 393, in _run_image
    return self._run_image_with_mounts(self.mounts, add_tmp_variable=False)
           ^^^^^^^^^^^^^^^^^^^^^^^^^^^^^^^^^^^^^^^^^^^^^^^^^^^^^^^^^^^^^^^^
  File "/home/airflow/.local/lib/python3.12/site-packages/airflow/providers/docker/operators/docker.py", line 453, in _run_image_with_mounts
    raise DockerContainerFailedException(f"Docker container failed: {result!r}", logs=log_lines)
airflow.providers.docker.exceptions.DockerContainerFailedException: Docker container failed: {'StatusCode': 1}
[2024-12-20T18:36:10.386+0000] {local_task_job_runner.py:266} INFO - Task exited with return code 1
[2024-12-20T18:36:10.428+0000] {taskinstance.py:3895} INFO - 0 downstream tasks scheduled from follow-on schedule check
[2024-12-20T18:36:10.429+0000] {local_task_job_runner.py:245} INFO - ::endgroup::
