[2024-12-20T12:27:14.989+0000] {local_task_job_runner.py:123} INFO - ::group::Pre task execution logs
[2024-12-20T12:27:15.005+0000] {taskinstance.py:2613} INFO - Dependencies all met for dep_context=non-requeueable deps ti=<TaskInstance: docker_dag.t2 scheduled__2024-12-19T00:00:00+00:00 [queued]>
[2024-12-20T12:27:15.015+0000] {taskinstance.py:2613} INFO - Dependencies all met for dep_context=requeueable deps ti=<TaskInstance: docker_dag.t2 scheduled__2024-12-19T00:00:00+00:00 [queued]>
[2024-12-20T12:27:15.016+0000] {taskinstance.py:2866} INFO - Starting attempt 1 of 1
[2024-12-20T12:27:15.026+0000] {taskinstance.py:2889} INFO - Executing <Task(DockerOperator): t2> on 2024-12-19 00:00:00+00:00
[2024-12-20T12:27:15.046+0000] {warnings.py:112} WARNING - /home/***/.local/lib/python3.12/site-packages/***/task/task_runner/standard_task_runner.py:70: DeprecationWarning: This process (pid=88) is multi-threaded, use of fork() may lead to deadlocks in the child.
  pid = os.fork()

[2024-12-20T12:27:15.050+0000] {standard_task_runner.py:72} INFO - Started process 90 to run task
[2024-12-20T12:27:15.050+0000] {standard_task_runner.py:104} INFO - Running: ['***', 'tasks', 'run', 'docker_dag', 't2', 'scheduled__2024-12-19T00:00:00+00:00', '--job-id', '21', '--raw', '--subdir', 'DAGS_FOLDER/A_dag_test.py', '--cfg-path', '/tmp/tmp1eueflam']
[2024-12-20T12:27:15.055+0000] {standard_task_runner.py:105} INFO - Job 21: Subtask t2
[2024-12-20T12:27:15.126+0000] {task_command.py:467} INFO - Running <TaskInstance: docker_dag.t2 scheduled__2024-12-19T00:00:00+00:00 [running]> on host 022c719b23d2
[2024-12-20T12:27:15.263+0000] {taskinstance.py:3132} INFO - Exporting env vars: AIRFLOW_CTX_DAG_OWNER='***' AIRFLOW_CTX_DAG_ID='docker_dag' AIRFLOW_CTX_TASK_ID='t2' AIRFLOW_CTX_EXECUTION_DATE='2024-12-19T00:00:00+00:00' AIRFLOW_CTX_TRY_NUMBER='1' AIRFLOW_CTX_DAG_RUN_ID='scheduled__2024-12-19T00:00:00+00:00'
[2024-12-20T12:27:15.267+0000] {logging_mixin.py:190} INFO - Task instance is in running state
[2024-12-20T12:27:15.267+0000] {logging_mixin.py:190} INFO -  Previous state of the Task instance: queued
[2024-12-20T12:27:15.268+0000] {logging_mixin.py:190} INFO - Current task name:t2 state:running start_date:2024-12-20 12:27:15.006387+00:00
[2024-12-20T12:27:15.269+0000] {logging_mixin.py:190} INFO - Dag name:docker_dag and current dag run status:running
[2024-12-20T12:27:15.270+0000] {taskinstance.py:731} INFO - ::endgroup::
[2024-12-20T12:27:15.289+0000] {docker.py:157} ERROR - Failed to establish connection to Docker host unix://var/run/docker.sock: Error while fetching server API version: ('Connection aborted.', FileNotFoundError(2, 'No such file or directory'))
[2024-12-20T12:27:15.309+0000] {taskinstance.py:3311} ERROR - Task failed with exception
Traceback (most recent call last):
  File "/home/airflow/.local/lib/python3.12/site-packages/airflow/models/taskinstance.py", line 767, in _execute_task
    result = _execute_callable(context=context, **execute_callable_kwargs)
             ^^^^^^^^^^^^^^^^^^^^^^^^^^^^^^^^^^^^^^^^^^^^^^^^^^^^^^^^^^^^^
  File "/home/airflow/.local/lib/python3.12/site-packages/airflow/models/taskinstance.py", line 733, in _execute_callable
    return ExecutionCallableRunner(
           ^^^^^^^^^^^^^^^^^^^^^^^^
  File "/home/airflow/.local/lib/python3.12/site-packages/airflow/utils/operator_helpers.py", line 252, in run
    return self.func(*args, **kwargs)
           ^^^^^^^^^^^^^^^^^^^^^^^^^^
  File "/home/airflow/.local/lib/python3.12/site-packages/airflow/models/baseoperator.py", line 422, in wrapper
    return func(self, *args, **kwargs)
           ^^^^^^^^^^^^^^^^^^^^^^^^^^^
  File "/home/airflow/.local/lib/python3.12/site-packages/airflow/providers/docker/operators/docker.py", line 501, in execute
    if self.force_pull or not self.cli.images(name=self.image):
                              ^^^^^^^^
  File "/home/airflow/.local/lib/python3.12/site-packages/airflow/providers/docker/operators/docker.py", line 375, in cli
    return self.hook.api_client
           ^^^^^^^^^^^^^^^^^^^^
  File "/usr/local/lib/python3.12/functools.py", line 995, in __get__
    val = self.func(instance)
          ^^^^^^^^^^^^^^^^^^^
  File "/home/airflow/.local/lib/python3.12/site-packages/airflow/providers/docker/hooks/docker.py", line 161, in api_client
    raise AirflowException("Failed to establish connection to any given Docker hosts.")
airflow.exceptions.AirflowException: Failed to establish connection to any given Docker hosts.
[2024-12-20T12:27:15.315+0000] {logging_mixin.py:190} INFO - Task instance in failure state
[2024-12-20T12:27:15.316+0000] {logging_mixin.py:190} INFO - Task start:2024-12-20 12:27:15.006387+00:00 end:2024-12-20 12:27:15.314061+00:00 duration:0.307674
[2024-12-20T12:27:15.317+0000] {logging_mixin.py:190} INFO - Task:<Task(DockerOperator): t2> dag:<DAG: docker_dag> dagrun:<DagRun docker_dag @ 2024-12-19 00:00:00+00:00: scheduled__2024-12-19T00:00:00+00:00, state:running, queued_at: 2024-12-20 12:27:03.962093+00:00. externally triggered: False>
[2024-12-20T12:27:15.318+0000] {logging_mixin.py:190} INFO - Failure caused by Failed to establish connection to any given Docker hosts.
[2024-12-20T12:27:15.320+0000] {taskinstance.py:1225} INFO - Marking task as FAILED. dag_id=docker_dag, task_id=t2, run_id=scheduled__2024-12-19T00:00:00+00:00, execution_date=20241219T000000, start_date=20241220T122715, end_date=20241220T122715
[2024-12-20T12:27:15.339+0000] {taskinstance.py:340} INFO - ::group::Post task execution logs
[2024-12-20T12:27:15.340+0000] {standard_task_runner.py:124} ERROR - Failed to execute job 21 for task t2 (Failed to establish connection to any given Docker hosts.; 90)
Traceback (most recent call last):
  File "/home/airflow/.local/lib/python3.12/site-packages/airflow/task/task_runner/standard_task_runner.py", line 117, in _start_by_fork
    ret = args.func(args, dag=self.dag)
          ^^^^^^^^^^^^^^^^^^^^^^^^^^^^^
  File "/home/airflow/.local/lib/python3.12/site-packages/airflow/cli/cli_config.py", line 49, in command
    return func(*args, **kwargs)
           ^^^^^^^^^^^^^^^^^^^^^
  File "/home/airflow/.local/lib/python3.12/site-packages/airflow/utils/cli.py", line 116, in wrapper
    return f(*args, **kwargs)
           ^^^^^^^^^^^^^^^^^^
  File "/home/airflow/.local/lib/python3.12/site-packages/airflow/cli/commands/task_command.py", line 483, in task_run
    task_return_code = _run_task_by_selected_method(args, _dag, ti)
                       ^^^^^^^^^^^^^^^^^^^^^^^^^^^^^^^^^^^^^^^^^^^^
  File "/home/airflow/.local/lib/python3.12/site-packages/airflow/cli/commands/task_command.py", line 256, in _run_task_by_selected_method
    return _run_raw_task(args, ti)
           ^^^^^^^^^^^^^^^^^^^^^^^
  File "/home/airflow/.local/lib/python3.12/site-packages/airflow/cli/commands/task_command.py", line 341, in _run_raw_task
    return ti._run_raw_task(
           ^^^^^^^^^^^^^^^^^
  File "/home/airflow/.local/lib/python3.12/site-packages/airflow/utils/session.py", line 97, in wrapper
    return func(*args, session=session, **kwargs)
           ^^^^^^^^^^^^^^^^^^^^^^^^^^^^^^^^^^^^^^
  File "/home/airflow/.local/lib/python3.12/site-packages/airflow/models/taskinstance.py", line 3005, in _run_raw_task
    return _run_raw_task(
           ^^^^^^^^^^^^^^
  File "/home/airflow/.local/lib/python3.12/site-packages/airflow/models/taskinstance.py", line 273, in _run_raw_task
    TaskInstance._execute_task_with_callbacks(
  File "/home/airflow/.local/lib/python3.12/site-packages/airflow/models/taskinstance.py", line 3159, in _execute_task_with_callbacks
    result = self._execute_task(context, task_orig)
             ^^^^^^^^^^^^^^^^^^^^^^^^^^^^^^^^^^^^^^
  File "/home/airflow/.local/lib/python3.12/site-packages/airflow/models/taskinstance.py", line 3183, in _execute_task
    return _execute_task(self, context, task_orig)
           ^^^^^^^^^^^^^^^^^^^^^^^^^^^^^^^^^^^^^^^
  File "/home/airflow/.local/lib/python3.12/site-packages/airflow/models/taskinstance.py", line 767, in _execute_task
    result = _execute_callable(context=context, **execute_callable_kwargs)
             ^^^^^^^^^^^^^^^^^^^^^^^^^^^^^^^^^^^^^^^^^^^^^^^^^^^^^^^^^^^^^
  File "/home/airflow/.local/lib/python3.12/site-packages/airflow/models/taskinstance.py", line 733, in _execute_callable
    return ExecutionCallableRunner(
           ^^^^^^^^^^^^^^^^^^^^^^^^
  File "/home/airflow/.local/lib/python3.12/site-packages/airflow/utils/operator_helpers.py", line 252, in run
    return self.func(*args, **kwargs)
           ^^^^^^^^^^^^^^^^^^^^^^^^^^
  File "/home/airflow/.local/lib/python3.12/site-packages/airflow/models/baseoperator.py", line 422, in wrapper
    return func(self, *args, **kwargs)
           ^^^^^^^^^^^^^^^^^^^^^^^^^^^
  File "/home/airflow/.local/lib/python3.12/site-packages/airflow/providers/docker/operators/docker.py", line 501, in execute
    if self.force_pull or not self.cli.images(name=self.image):
                              ^^^^^^^^
  File "/home/airflow/.local/lib/python3.12/site-packages/airflow/providers/docker/operators/docker.py", line 375, in cli
    return self.hook.api_client
           ^^^^^^^^^^^^^^^^^^^^
  File "/usr/local/lib/python3.12/functools.py", line 995, in __get__
    val = self.func(instance)
          ^^^^^^^^^^^^^^^^^^^
  File "/home/airflow/.local/lib/python3.12/site-packages/airflow/providers/docker/hooks/docker.py", line 161, in api_client
    raise AirflowException("Failed to establish connection to any given Docker hosts.")
airflow.exceptions.AirflowException: Failed to establish connection to any given Docker hosts.
[2024-12-20T12:27:15.366+0000] {local_task_job_runner.py:266} INFO - Task exited with return code 1
[2024-12-20T12:27:15.409+0000] {taskinstance.py:3895} INFO - 0 downstream tasks scheduled from follow-on schedule check
[2024-12-20T12:27:15.411+0000] {local_task_job_runner.py:245} INFO - ::endgroup::
