[2025-01-05T13:55:30.136+0000] {local_task_job_runner.py:123} INFO - ::group::Pre task execution logs
[2025-01-05T13:55:30.179+0000] {taskinstance.py:2613} INFO - Dependencies all met for dep_context=non-requeueable deps ti=<TaskInstance: dag_spark_cluster.spark_action manual__2025-01-05T13:55:27.134274+00:00 [queued]>
[2025-01-05T13:55:30.197+0000] {taskinstance.py:2613} INFO - Dependencies all met for dep_context=requeueable deps ti=<TaskInstance: dag_spark_cluster.spark_action manual__2025-01-05T13:55:27.134274+00:00 [queued]>
[2025-01-05T13:55:30.199+0000] {taskinstance.py:2866} INFO - Starting attempt 1 of 1
[2025-01-05T13:55:30.228+0000] {taskinstance.py:2889} INFO - Executing <Task(PythonOperator): spark_action> on 2025-01-05 13:55:27.134274+00:00
[2025-01-05T13:55:30.258+0000] {warnings.py:112} WARNING - /home/***/.local/lib/python3.12/site-packages/***/task/task_runner/standard_task_runner.py:70: DeprecationWarning: This process (pid=158) is multi-threaded, use of fork() may lead to deadlocks in the child.
  pid = os.fork()

[2025-01-05T13:55:30.260+0000] {standard_task_runner.py:72} INFO - Started process 159 to run task
[2025-01-05T13:55:30.266+0000] {standard_task_runner.py:104} INFO - Running: ['***', 'tasks', 'run', 'dag_spark_cluster', 'spark_action', 'manual__2025-01-05T13:55:27.134274+00:00', '--job-id', '571', '--raw', '--subdir', 'DAGS_FOLDER/dag_spark_cluster.py', '--cfg-path', '/tmp/tmpn3tvdcek']
[2025-01-05T13:55:30.268+0000] {standard_task_runner.py:105} INFO - Job 571: Subtask spark_action
[2025-01-05T13:55:30.426+0000] {task_command.py:467} INFO - Running <TaskInstance: dag_spark_cluster.spark_action manual__2025-01-05T13:55:27.134274+00:00 [running]> on host 44275986e897
[2025-01-05T13:55:30.607+0000] {taskinstance.py:3132} INFO - Exporting env vars: AIRFLOW_CTX_DAG_OWNER='Anoop M' AIRFLOW_CTX_DAG_ID='dag_spark_cluster' AIRFLOW_CTX_TASK_ID='spark_action' AIRFLOW_CTX_EXECUTION_DATE='2025-01-05T13:55:27.134274+00:00' AIRFLOW_CTX_TRY_NUMBER='1' AIRFLOW_CTX_DAG_RUN_ID='manual__2025-01-05T13:55:27.134274+00:00'
[2025-01-05T13:55:30.610+0000] {taskinstance.py:731} INFO - ::endgroup::
[2025-01-05T13:55:32.766+0000] {logging_mixin.py:190} INFO - spark-master removed
[2025-01-05T13:55:34.077+0000] {taskinstance.py:3311} ERROR - Task failed with exception
Traceback (most recent call last):
  File "/home/airflow/.local/lib/python3.12/site-packages/docker/api/client.py", line 275, in _raise_for_status
    response.raise_for_status()
  File "/home/airflow/.local/lib/python3.12/site-packages/requests/models.py", line 1024, in raise_for_status
    raise HTTPError(http_error_msg, response=self)
requests.exceptions.HTTPError: 409 Client Error: Conflict for url: http+docker://localhost/v1.47/containers/fc2ac179aef4e250cc3c7ec3ad16e384dd081c040bb2464a91cc0d625170604b?v=False&link=False&force=False

The above exception was the direct cause of the following exception:

Traceback (most recent call last):
  File "/home/airflow/.local/lib/python3.12/site-packages/airflow/models/taskinstance.py", line 767, in _execute_task
    result = _execute_callable(context=context, **execute_callable_kwargs)
             ^^^^^^^^^^^^^^^^^^^^^^^^^^^^^^^^^^^^^^^^^^^^^^^^^^^^^^^^^^^^^
  File "/home/airflow/.local/lib/python3.12/site-packages/airflow/models/taskinstance.py", line 733, in _execute_callable
    return ExecutionCallableRunner(
           ^^^^^^^^^^^^^^^^^^^^^^^^
  File "/home/airflow/.local/lib/python3.12/site-packages/airflow/utils/operator_helpers.py", line 252, in run
    return self.func(*args, **kwargs)
           ^^^^^^^^^^^^^^^^^^^^^^^^^^
  File "/home/airflow/.local/lib/python3.12/site-packages/airflow/models/baseoperator.py", line 422, in wrapper
    return func(self, *args, **kwargs)
           ^^^^^^^^^^^^^^^^^^^^^^^^^^^
  File "/home/airflow/.local/lib/python3.12/site-packages/airflow/operators/python.py", line 238, in execute
    return_value = self.execute_callable()
                   ^^^^^^^^^^^^^^^^^^^^^^^
  File "/home/airflow/.local/lib/python3.12/site-packages/airflow/operators/python.py", line 256, in execute_callable
    return runner.run(*self.op_args, **self.op_kwargs)
           ^^^^^^^^^^^^^^^^^^^^^^^^^^^^^^^^^^^^^^^^^^^
  File "/home/airflow/.local/lib/python3.12/site-packages/airflow/utils/operator_helpers.py", line 252, in run
    return self.func(*args, **kwargs)
           ^^^^^^^^^^^^^^^^^^^^^^^^^^
  File "/opt/airflow/dags/dag_spark_cluster.py", line 78, in spark_action
    stop_spark_containers()
  File "/opt/airflow/dags/dag_spark_cluster.py", line 65, in stop_spark_containers
    client.containers.get(container).remove()
  File "/home/airflow/.local/lib/python3.12/site-packages/docker/models/containers.py", line 367, in remove
    return self.client.api.remove_container(self.id, **kwargs)
           ^^^^^^^^^^^^^^^^^^^^^^^^^^^^^^^^^^^^^^^^^^^^^^^^^^^
  File "/home/airflow/.local/lib/python3.12/site-packages/docker/utils/decorators.py", line 19, in wrapped
    return f(self, resource_id, *args, **kwargs)
           ^^^^^^^^^^^^^^^^^^^^^^^^^^^^^^^^^^^^^
  File "/home/airflow/.local/lib/python3.12/site-packages/docker/api/container.py", line 1037, in remove_container
    self._raise_for_status(res)
  File "/home/airflow/.local/lib/python3.12/site-packages/docker/api/client.py", line 277, in _raise_for_status
    raise create_api_error_from_http_exception(e) from e
          ^^^^^^^^^^^^^^^^^^^^^^^^^^^^^^^^^^^^^^^
  File "/home/airflow/.local/lib/python3.12/site-packages/docker/errors.py", line 39, in create_api_error_from_http_exception
    raise cls(e, response=response, explanation=explanation) from e
docker.errors.APIError: 409 Client Error for http+docker://localhost/v1.47/containers/fc2ac179aef4e250cc3c7ec3ad16e384dd081c040bb2464a91cc0d625170604b?v=False&link=False&force=False: Conflict ("removal of container fc2ac179aef4e250cc3c7ec3ad16e384dd081c040bb2464a91cc0d625170604b is already in progress")
[2025-01-05T13:55:34.325+0000] {taskinstance.py:1225} INFO - Marking task as FAILED. dag_id=dag_spark_cluster, task_id=spark_action, run_id=manual__2025-01-05T13:55:27.134274+00:00, execution_date=20250105T135527, start_date=20250105T135530, end_date=20250105T135534
[2025-01-05T13:55:34.658+0000] {taskinstance.py:340} INFO - ::group::Post task execution logs
[2025-01-05T13:55:34.705+0000] {standard_task_runner.py:124} ERROR - Failed to execute job 571 for task spark_action (409 Client Error for http+docker://localhost/v1.47/containers/fc2ac179aef4e250cc3c7ec3ad16e384dd081c040bb2464a91cc0d625170604b?v=False&link=False&force=False: Conflict ("removal of container fc2ac179aef4e250cc3c7ec3ad16e384dd081c040bb2464a91cc0d625170604b is already in progress"); 159)
Traceback (most recent call last):
  File "/home/airflow/.local/lib/python3.12/site-packages/docker/api/client.py", line 275, in _raise_for_status
    response.raise_for_status()
  File "/home/airflow/.local/lib/python3.12/site-packages/requests/models.py", line 1024, in raise_for_status
    raise HTTPError(http_error_msg, response=self)
requests.exceptions.HTTPError: 409 Client Error: Conflict for url: http+docker://localhost/v1.47/containers/fc2ac179aef4e250cc3c7ec3ad16e384dd081c040bb2464a91cc0d625170604b?v=False&link=False&force=False

The above exception was the direct cause of the following exception:

Traceback (most recent call last):
  File "/home/airflow/.local/lib/python3.12/site-packages/airflow/task/task_runner/standard_task_runner.py", line 117, in _start_by_fork
    ret = args.func(args, dag=self.dag)
          ^^^^^^^^^^^^^^^^^^^^^^^^^^^^^
  File "/home/airflow/.local/lib/python3.12/site-packages/airflow/cli/cli_config.py", line 49, in command
    return func(*args, **kwargs)
           ^^^^^^^^^^^^^^^^^^^^^
  File "/home/airflow/.local/lib/python3.12/site-packages/airflow/utils/cli.py", line 116, in wrapper
    return f(*args, **kwargs)
           ^^^^^^^^^^^^^^^^^^
  File "/home/airflow/.local/lib/python3.12/site-packages/airflow/cli/commands/task_command.py", line 483, in task_run
    task_return_code = _run_task_by_selected_method(args, _dag, ti)
                       ^^^^^^^^^^^^^^^^^^^^^^^^^^^^^^^^^^^^^^^^^^^^
  File "/home/airflow/.local/lib/python3.12/site-packages/airflow/cli/commands/task_command.py", line 256, in _run_task_by_selected_method
    return _run_raw_task(args, ti)
           ^^^^^^^^^^^^^^^^^^^^^^^
  File "/home/airflow/.local/lib/python3.12/site-packages/airflow/cli/commands/task_command.py", line 341, in _run_raw_task
    return ti._run_raw_task(
           ^^^^^^^^^^^^^^^^^
  File "/home/airflow/.local/lib/python3.12/site-packages/airflow/utils/session.py", line 97, in wrapper
    return func(*args, session=session, **kwargs)
           ^^^^^^^^^^^^^^^^^^^^^^^^^^^^^^^^^^^^^^
  File "/home/airflow/.local/lib/python3.12/site-packages/airflow/models/taskinstance.py", line 3005, in _run_raw_task
    return _run_raw_task(
           ^^^^^^^^^^^^^^
  File "/home/airflow/.local/lib/python3.12/site-packages/airflow/models/taskinstance.py", line 273, in _run_raw_task
    TaskInstance._execute_task_with_callbacks(
  File "/home/airflow/.local/lib/python3.12/site-packages/airflow/models/taskinstance.py", line 3159, in _execute_task_with_callbacks
    result = self._execute_task(context, task_orig)
             ^^^^^^^^^^^^^^^^^^^^^^^^^^^^^^^^^^^^^^
  File "/home/airflow/.local/lib/python3.12/site-packages/airflow/models/taskinstance.py", line 3183, in _execute_task
    return _execute_task(self, context, task_orig)
           ^^^^^^^^^^^^^^^^^^^^^^^^^^^^^^^^^^^^^^^
  File "/home/airflow/.local/lib/python3.12/site-packages/airflow/models/taskinstance.py", line 767, in _execute_task
    result = _execute_callable(context=context, **execute_callable_kwargs)
             ^^^^^^^^^^^^^^^^^^^^^^^^^^^^^^^^^^^^^^^^^^^^^^^^^^^^^^^^^^^^^
  File "/home/airflow/.local/lib/python3.12/site-packages/airflow/models/taskinstance.py", line 733, in _execute_callable
    return ExecutionCallableRunner(
           ^^^^^^^^^^^^^^^^^^^^^^^^
  File "/home/airflow/.local/lib/python3.12/site-packages/airflow/utils/operator_helpers.py", line 252, in run
    return self.func(*args, **kwargs)
           ^^^^^^^^^^^^^^^^^^^^^^^^^^
  File "/home/airflow/.local/lib/python3.12/site-packages/airflow/models/baseoperator.py", line 422, in wrapper
    return func(self, *args, **kwargs)
           ^^^^^^^^^^^^^^^^^^^^^^^^^^^
  File "/home/airflow/.local/lib/python3.12/site-packages/airflow/operators/python.py", line 238, in execute
    return_value = self.execute_callable()
                   ^^^^^^^^^^^^^^^^^^^^^^^
  File "/home/airflow/.local/lib/python3.12/site-packages/airflow/operators/python.py", line 256, in execute_callable
    return runner.run(*self.op_args, **self.op_kwargs)
           ^^^^^^^^^^^^^^^^^^^^^^^^^^^^^^^^^^^^^^^^^^^
  File "/home/airflow/.local/lib/python3.12/site-packages/airflow/utils/operator_helpers.py", line 252, in run
    return self.func(*args, **kwargs)
           ^^^^^^^^^^^^^^^^^^^^^^^^^^
  File "/opt/airflow/dags/dag_spark_cluster.py", line 78, in spark_action
    stop_spark_containers()
  File "/opt/airflow/dags/dag_spark_cluster.py", line 65, in stop_spark_containers
    client.containers.get(container).remove()
  File "/home/airflow/.local/lib/python3.12/site-packages/docker/models/containers.py", line 367, in remove
    return self.client.api.remove_container(self.id, **kwargs)
           ^^^^^^^^^^^^^^^^^^^^^^^^^^^^^^^^^^^^^^^^^^^^^^^^^^^
  File "/home/airflow/.local/lib/python3.12/site-packages/docker/utils/decorators.py", line 19, in wrapped
    return f(self, resource_id, *args, **kwargs)
           ^^^^^^^^^^^^^^^^^^^^^^^^^^^^^^^^^^^^^
  File "/home/airflow/.local/lib/python3.12/site-packages/docker/api/container.py", line 1037, in remove_container
    self._raise_for_status(res)
  File "/home/airflow/.local/lib/python3.12/site-packages/docker/api/client.py", line 277, in _raise_for_status
    raise create_api_error_from_http_exception(e) from e
          ^^^^^^^^^^^^^^^^^^^^^^^^^^^^^^^^^^^^^^^
  File "/home/airflow/.local/lib/python3.12/site-packages/docker/errors.py", line 39, in create_api_error_from_http_exception
    raise cls(e, response=response, explanation=explanation) from e
docker.errors.APIError: 409 Client Error for http+docker://localhost/v1.47/containers/fc2ac179aef4e250cc3c7ec3ad16e384dd081c040bb2464a91cc0d625170604b?v=False&link=False&force=False: Conflict ("removal of container fc2ac179aef4e250cc3c7ec3ad16e384dd081c040bb2464a91cc0d625170604b is already in progress")
[2025-01-05T13:55:34.893+0000] {local_task_job_runner.py:266} INFO - Task exited with return code 1
[2025-01-05T13:55:35.184+0000] {taskinstance.py:3895} INFO - 0 downstream tasks scheduled from follow-on schedule check
[2025-01-05T13:55:35.189+0000] {local_task_job_runner.py:245} INFO - ::endgroup::
[2025-01-05T13:55:35.275+0000] {standard_task_runner.py:217} INFO - Process not found (most likely exited), stop collecting metrics
